Workbook

Sheet Inputs
A1: Is the Indian Stock Market Rally Healthy?
A2: Index-level analysis. Fixed question: is the October 2026 rebound broad-based, or driven by a few heavyweights?
A4: Item | B4: Value | C4: Note
A5: Analysis end date | B5: =MAX(Prices!$A$2:$A$247) -> 46311 | C5: Last trading day in the data.
A6: Analysis window start (3 months) | B6: =EDATE(B5,-3) -> 46219 | C6: End date minus 3 months.
A7: Rebound start date | B7: 46303 | C7: Lowest Nifty 50 closing price in the data (closing prices, not intraday). Nifty 50 closed 15.6% below its 2 Jan 2026 high on this day. Not every index bottomed here: Bank and IT on 29 Sep, FMCG on 1 Oct, Smallcap 100 on 24 Jul. All indices are measured from the Nifty 50 low so the comparison is on the same dates.
A8: Helper: date of lowest Nifty 50 close in the data | B8: =INDEX(Prices!$A$2:$A$247,MATCH(MIN(Prices!$B$2:$B$247),Prices!$B$2:$B$247,0)) -> 46303 | C8: Lowest close in the whole year of data.
A9: Trading days in 1 week | B9: 5 | C9: Approximate. Input.
A10: Trading days in 1 month | B10: 21 | C10: Approximate. Input.
A11: Trading days in 3 months | B11: 63 | C11: Approximate. Input.
A12: Position of last date | B12: =COUNT(Prices!$A$2:$A$247) -> 246 | C12: Row number inside the Prices date list.
A13: Position of window start | B13: =MATCH(B6,Prices!$A$2:$A$247,1) -> 182 | C13: Last trading day on or before the window start date.
A14: Position of rebound start | B14: =MATCH(B7,Prices!$A$2:$A$247,0) -> 240 | C14: Must be a date that exists in Prices.
A15: Signal threshold (percentage points) | B15: 0.02 | C15: 2.0% = a gap of 2 percentage points. Basis: over the past year, a 6-trading-day gap between Nifty 50 and Midcap 100 returns was bigger than 1 point about 35% of the time (normal noise) but bigger than 2 points only about 7% of the time. Typical gap (standard deviation) is about 1.1 points vs Midcap and 1.6 vs Smallcap. You may change it.
A16: Trading days per year (annualising) | B16: 252 | C16: Standard convention.
A17: Days in analysis window | B17: =B12-B13+1 -> 65 | C17: Drawdown and Rebased sheets have exactly this many rows.
A18: Check: blank cells in Prices | B18: =COUNTBLANK(Prices!$B$2:$H$247) -> 0 | C18: Must be 0.
A20: Legend
A21: Blue text = typed input
A22: Black text = formula
A23: Yellow fill = your decision
A25: Limits of this version
A26: NIFTY 50 EQUAL WEIGHT is not in the data, so the cap-weighted vs equal-weighted test is not done. Large vs mid vs small caps is used instead.
A27: Breadth (how many of the 50 stocks rose) needs the 50 stock price files. Not included yet.
A28: NIFTY FMCG and NIFTY AUTO are extra sectors for the sector view.

Sheet Summary
A1: Summary: key numbers by index
A3: Index | B3: Rebound return | C3: 3-month return | D3: Window volatility (annualised) | E3: Max drawdown (window) | F3: Latest 20-day volatility
A4: =Prices!B1 -> NIFTY 50 | B4: =Returns!E4 -> 0.041128024 | C4: =Returns!D4 -> -0.048826143 | D4: =STDEV(INDEX(Daily!B$2:B$247,Inputs!$B$13+1):INDEX(Daily!B$2:B$247,Inputs!$B$12))*SQRT(Inputs!$B$16) -> 0.11469343 | E4: =Drawdown!B68 -> -0.10262651 | F4: =Volatility!B247 -> 0.16078299
A5: =Prices!C1 -> NIFTY MIDCAP 100 | B5: =Returns!E5 -> 0.021547964 | C5: =Returns!D5 -> -0.052833622 | D5: =STDEV(INDEX(Daily!C$2:C$247,Inputs!$B$13+1):INDEX(Daily!C$2:C$247,Inputs!$B$12))*SQRT(Inputs!$B$16) -> 0.1270507 | E5: =Drawdown!C68 -> -0.098750871 | F5: =Volatility!C247 -> 0.17577217
A6: =Prices!D1 -> NIFTY SMALLCAP 100 | B6: =Returns!E6 -> 0.0041837051 | C6: =Returns!D6 -> -0.0086285972 | D6: =STDEV(INDEX(Daily!D$2:D$247,Inputs!$B$13+1):INDEX(Daily!D$2:D$247,Inputs!$B$12))*SQRT(Inputs!$B$16) -> 0.13666052 | E6: =Drawdown!D68 -> -0.053822562 | F6: =Volatility!D247 -> 0.17667639
A7: =Prices!E1 -> NIFTY BANK | B7: =Returns!E7 -> 0.024377672 | C7: =Returns!D7 -> -0.045750785 | D7: =STDEV(INDEX(Daily!E$2:E$247,Inputs!$B$13+1):INDEX(Daily!E$2:E$247,Inputs!$B$12))*SQRT(Inputs!$B$16) -> 0.11974238 | E7: =Drawdown!E68 -> -0.072818661 | F7: =Volatility!E247 -> 0.14326824
A8: =Prices!F1 -> NIFTY IT | B8: =Returns!E8 -> 0.1509738 | C8: =Returns!D8 -> 0.092296059 | D8: =STDEV(INDEX(Daily!F$2:F$247,Inputs!$B$13+1):INDEX(Daily!F$2:F$247,Inputs!$B$12))*SQRT(Inputs!$B$16) -> 0.25688733 | E8: =Drawdown!F68 -> -0.13050719 | F8: =Volatility!F247 -> 0.29250712
A9: =Prices!G1 -> NIFTY FMCG | B9: =Returns!E9 -> 0.016358358 | C9: =Returns!D9 -> -0.084772517 | D9: =STDEV(INDEX(Daily!G$2:G$247,Inputs!$B$13+1):INDEX(Daily!G$2:G$247,Inputs!$B$12))*SQRT(Inputs!$B$16) -> 0.15583384 | E9: =Drawdown!G68 -> -0.12360004 | F9: =Volatility!G247 -> 0.20862876
A10: =Prices!H1 -> NIFTY AUTO | B10: =Returns!E10 -> 0.051230587 | C10: =Returns!D10 -> -0.049124069 | D10: =STDEV(INDEX(Daily!H$2:H$247,Inputs!$B$13+1):INDEX(Daily!H$2:H$247,Inputs!$B$12))*SQRT(Inputs!$B$16) -> 0.17006 | E10: =Drawdown!H68 -> -0.1732062 | F10: =Volatility!H247 -> 0.21916609
A12: Check these numbers against the NSE site before publishing. The rebound start date and the window dates are set on the Inputs sheet.

Sheet Prices
A1: Date | B1: NIFTY 50 | C1: NIFTY MIDCAP 100 | D1: NIFTY SMALLCAP 100 | E1: NIFTY BANK | F1: NIFTY IT | G1: NIFTY FMCG | H1: NIFTY AUTO
A2: 45950 | B2: =IF(COUNTIFS(Data!$A$2:$A$1723,B$1,Data!$B$2:$B$1723,$A2)=0,"",SUMIFS(Data!$F$2:$F$1723,Data!$A$2:$A$1723,B$1,Data!$B$2:$B$1723,$A2)) -> 25843.15 | C2: =IF(COUNTIFS(Data!$A$2:$A$1723,C$1,Data!$B$2:$B$1723,$A2)=0,"",SUMIFS(Data!$F$2:$F$1723,Data!$A$2:$A$1723,C$1,Data!$B$2:$B$1723,$A2)) -> 59344.5 | D2: =IF(COUNTIFS(Data!$A$2:$A$1723,D$1,Data!$B$2:$B$1723,$A2)=0,"",SUMIFS(Data!$F$2:$F$1723,Data!$A$2:$A$1723,D$1,Data!$B$2:$B$1723,$A2)) -> 18206.15 | E2: =IF(COUNTIFS(Data!$A$2:$A$1723,E$1,Data!$B$2:$B$1723,$A2)=0,"",SUMIFS(Data!$F$2:$F$1723,Data!$A$2:$A$1723,E$1,Data!$B$2:$B$1723,$A2)) -> 58033.2 | F2: =IF(COUNTIFS(Data!$A$2:$A$1723,F$1,Data!$B$2:$B$1723,$A2)=0,"",SUMIFS(Data!$F$2:$F$1723,Data!$A$2:$A$1723,F$1,Data!$B$2:$B$1723,$A2)) -> 35292.6 | G2: =IF(COUNTIFS(Data!$A$2:$A$1723,G$1,Data!$B$2:$B$1723,$A2)=0,"",SUMIFS(Data!$F$2:$F$1723,Data!$A$2:$A$1723,G$1,Data!$B$2:$B$1723,$A2)) -> 56597.15 | H2: =IF(COUNTIFS(Data!$A$2:$A$1723,H$1,Data!$B$2:$B$1723,$A2)=0,"",SUMIFS(Data!$F$2:$F$1723,Data!$A$2:$A$1723,H$1,Data!$B$2:$B$1723,$A2)) -> 27185.45
A3: 45951 | B3: =IF(COUNTIFS(Data!$A$2:$A$1723,B$1,Data!$B$2:$B$1723,$A3)=0,"",SUMIFS(Data!$F$2:$F$1723,Data!$A$2:$A$1723,B$1,Data!$B$2:$B$1723,$A3)) -> 25868.6 | C3: =IF(COUNTIFS(Data!$A$2:$A$1723,C$1,Data!$B$2:$B$1723,$A3)=0,"",SUMIFS(Data!$F$2:$F$1723,Data!$A$2:$A$1723,C$1,Data!$B$2:$B$1723,$A3)) -> 59409.55 | D3: =IF(COUNTIFS(Data!$A$2:$A$1723,D$1,Data!$B$2:$B$1723,$A3)=0,"",SUMIFS(Data!$F$2:$F$1723,Data!$A$2:$A$1723,D$1,Data!$B$2:$B$1723,$A3)) -> 18300.65 | E3: =IF(COUNTIFS(Data!$A$2:$A$1723,E$1,Data!$B$2:$B$1723,$A3)=0,"",SUMIFS(Data!$F$2:$F$1723,Data!$A$2:$A$1723,E$1,Data!$B$2:$B$1723,$A3)) -> 58007.2 | F3: =IF(COUNTIFS(Data!$A$2:$A$1723,F$1,Data!$B$2:$B$1723,$A3)=0,"",SUMIFS(Data!$F$2:$F$1723,Data!$A$2:$A$1723,F$1,Data!$B$2:$B$1723,$A3)) -> 35299.75 | G3: =IF(COUNTIFS(Data!$A$2:$A$1723,G$1,Data!$B$2:$B$1723,$A3)=0,"",SUMIFS(Data!$F$2:$F$1723,Data!$A$2:$A$1723,G$1,Data!$B$2:$B$1723,$A3)) -> 56609.15 | H3: =IF(COUNTIFS(Data!$A$2:$A$1723,H$1,Data!$B$2:$B$1723,$A3)=0,"",SUMIFS(Data!$F$2:$F$1723,Data!$A$2:$A$1723,H$1,Data!$B$2:$B$1723,$A3)) -> 27229.85
A4: 45953 | B4: =IF(COUNTIFS(Data!$A$2:$A$1723,B$1,Data!$B$2:$B$1723,$A4)=0,"",SUMIFS(Data!$F$2:$F$1723,Data!$A$2:$A$1723,B$1,Data!$B$2:$B$1723,$A4)) -> 25891.4 | C4: =IF(COUNTIFS(Data!$A$2:$A$1723,C$1,Data!$B$2:$B$1723,$A4)=0,"",SUMIFS(Data!$F$2:$F$1723,Data!$A$2:$A$1723,C$1,Data!$B$2:$B$1723,$A4)) -> 59371.25 | D4: =IF(COUNTIFS(Data!$A$2:$A$1723,D$1,Data!$B$2:$B$1723,$A4)=0,"",SUMIFS(Data!$F$2:$F$1723,Data!$A$2:$A$1723,D$1,Data!$B$2:$B$1723,$A4)) -> 18291.45 | E4: =IF(COUNTIFS(Data!$A$2:$A$1723,E$1,Data!$B$2:$B$1723,$A4)=0,"",SUMIFS(Data!$F$2:$F$1723,Data!$A$2:$A$1723,E$1,Data!$B$2:$B$1723,$A4)) -> 58078.05 | F4: =IF(COUNTIFS(Data!$A$2:$A$1723,F$1,Data!$B$2:$B$1723,$A4)=0,"",SUMIFS(Data!$F$2:$F$1723,Data!$A$2:$A$1723,F$1,Data!$B$2:$B$1723,$A4)) -> 36078.65 | G4: =IF(COUNTIFS(Data!$A$2:$A$1723,G$1,Data!$B$2:$B$1723,$A4)=0,"",SUMIFS(Data!$F$2:$F$1723,Data!$A$2:$A$1723,G$1,Data!$B$2:$B$1723,$A4)) -> 56772.45 | H4: =IF(COUNTIFS(Data!$A$2:$A$1723,H$1,Data!$B$2:$B$1723,$A4)=0,"",SUMIFS(Data!$F$2:$F$1723,Data!$A$2:$A$1723,H$1,Data!$B$2:$B$1723,$A4)) -> 27218.75
A5: 45954 | B5: =IF(COUNTIFS(Data!$A$2:$A$1723,B$1,Data!$B$2:$B$1723,$A5)=0,"",SUMIFS(Data!$F$2:$F$1723,Data!$A$2:$A$1723,B$1,Data!$B$2:$B$1723,$A5)) -> 25795.15 | C5: =IF(COUNTIFS(Data!$A$2:$A$1723,C$1,Data!$B$2:$B$1723,$A5)=0,"",SUMIFS(Data!$F$2:$F$1723,Data!$A$2:$A$1723,C$1,Data!$B$2:$B$1723,$A5)) -> 59231.2 | D5: =IF(COUNTIFS(Data!$A$2:$A$1723,D$1,Data!$B$2:$B$1723,$A5)=0,"",SUMIFS(Data!$F$2:$F$1723,Data!$A$2:$A$1723,D$1,Data!$B$2:$B$1723,$A5)) -> 18253.35 | E5: =IF(COUNTIFS(Data!$A$2:$A$1723,E$1,Data!$B$2:$B$1723,$A5)=0,"",SUMIFS(Data!$F$2:$F$1723,Data!$A$2:$A$1723,E$1,Data!$B$2:$B$1723,$A5)) -> 57699.6 | F5: =IF(COUNTIFS(Data!$A$2:$A$1723,F$1,Data!$B$2:$B$1723,$A5)=0,"",SUMIFS(Data!$F$2:$F$1723,Data!$A$2:$A$1723,F$1,Data!$B$2:$B$1723,$A5)) -> 35986.35 | G5: =IF(COUNTIFS(Data!$A$2:$A$1723,G$1,Data!$B$2:$B$1723,$A5)=0,"",SUMIFS(Data!$F$2:$F$1723,Data!$A$2:$A$1723,G$1,Data!$B$2:$B$1723,$A5)) -> 56348.1 | H5: =IF(COUNTIFS(Data!$A$2:$A$1723,H$1,Data!$B$2:$B$1723,$A5)=0,"",SUMIFS(Data!$F$2:$F$1723,Data!$A$2:$A$1723,H$1,Data!$B$2:$B$1723,$A5)) -> 27108.7
A6: 45957 | B6: =IF(COUNTIFS(Data!$A$2:$A$1723,B$1,Data!$B$2:$B$1723,$A6)=0,"",SUMIFS(Data!$F$2:$F$1723,Data!$A$2:$A$1723,B$1,Data!$B$2:$B$1723,$A6)) -> 25966.05 | C6: =IF(COUNTIFS(Data!$A$2:$A$1723,C$1,Data!$B$2:$B$1723,$A6)=0,"",SUMIFS(Data!$F$2:$F$1723,Data!$A$2:$A$1723,C$1,Data!$B$2:$B$1723,$A6)) -> 59780.15 | D6: =IF(COUNTIFS(Data!$A$2:$A$1723,D$1,Data!$B$2:$B$1723,$A6)=0,"",SUMIFS(Data!$F$2:$F$1723,Data!$A$2:$A$1723,D$1,Data!$B$2:$B$1723,$A6)) -> 18403.05 | E6: =IF(COUNTIFS(Data!$A$2:$A$1723,E$1,Data!$B$2:$B$1723,$A6)=0,"",SUMIFS(Data!$F$2:$F$1723,Data!$A$2:$A$1723,E$1,Data!$B$2:$B$1723,$A6)) -> 58114.25 | F6: =IF(COUNTIFS(Data!$A$2:$A$1723,F$1,Data!$B$2:$B$1723,$A6)=0,"",SUMIFS(Data!$F$2:$F$1723,Data!$A$2:$A$1723,F$1,Data!$B$2:$B$1723,$A6)) -> 36129.1 | G6: =IF(COUNTIFS(Data!$A$2:$A$1723,G$1,Data!$B$2:$B$1723,$A6)=0,"",SUMIFS(Data!$F$2:$F$1723,Data!$A$2:$A$1723,G$1,Data!$B$2:$B$1723,$A6)) -> 56428.95 | H6: =IF(COUNTIFS(Data!$A$2:$A$1723,H$1,Data!$B$2:$B$1723,$A6)=0,"",SUMIFS(Data!$F$2:$F$1723,Data!$A$2:$A$1723,H$1,Data!$B$2:$B$1723,$A6)) -> 27263.65
A7: 45958 | B7: =IF(COUNTIFS(Data!$A$2:$A$1723,B$1,Data!$B$2:$B$1723,$A7)=0,"",SUMIFS(Data!$F$2:$F$1723,Data!$A$2:$A$1723,B$1,Data!$B$2:$B$1723,$A7)) -> 25936.2 | C7: =IF(COUNTIFS(Data!$A$2:$A$1723,C$1,Data!$B$2:$B$1723,$A7)=0,"",SUMIFS(Data!$F$2:$F$1723,Data!$A$2:$A$1723,C$1,Data!$B$2:$B$1723,$A7)) -> 59765.35 | D7: =IF(COUNTIFS(Data!$A$2:$A$1723,D$1,Data!$B$2:$B$1723,$A7)=0,"",SUMIFS(Data!$F$2:$F$1723,Data!$A$2:$A$1723,D$1,Data!$B$2:$B$1723,$A7)) -> 18407.6 | E7: =IF(COUNTIFS(Data!$A$2:$A$1723,E$1,Data!$B$2:$B$1723,$A7)=0,"",SUMIFS(Data!$F$2:$F$1723,Data!$A$2:$A$1723,E$1,Data!$B$2:$B$1723,$A7)) -> 58214.1 | F7: =IF(COUNTIFS(Data!$A$2:$A$1723,F$1,Data!$B$2:$B$1723,$A7)=0,"",SUMIFS(Data!$F$2:$F$1723,Data!$A$2:$A$1723,F$1,Data!$B$2:$B$1723,$A7)) -> 35860.4 | G7: =IF(COUNTIFS(Data!$A$2:$A$1723,G$1,Data!$B$2:$B$1723,$A7)=0,"",SUMIFS(Data!$F$2:$F$1723,Data!$A$2:$A$1723,G$1,Data!$B$2:$B$1723,$A7)) -> 56110.05 | H7: =IF(COUNTIFS(Data!$A$2:$A$1723,H$1,Data!$B$2:$B$1723,$A7)=0,"",SUMIFS(Data!$F$2:$F$1723,Data!$A$2:$A$1723,H$1,Data!$B$2:$B$1723,$A7)) -> 27148.35
A8: 45959 | B8: =IF(COUNTIFS(Data!$A$2:$A$1723,B$1,Data!$B$2:$B$1723,$A8)=0,"",SUMIFS(Data!$F$2:$F$1723,Data!$A$2:$A$1723,B$1,Data!$B$2:$B$1723,$A8)) -> 26053.9 | C8: =IF(COUNTIFS(Data!$A$2:$A$1723,C$1,Data!$B$2:$B$1723,$A8)=0,"",SUMIFS(Data!$F$2:$F$1723,Data!$A$2:$A$1723,C$1,Data!$B$2:$B$1723,$A8)) -> 60149.05 | D8: =IF(COUNTIFS(Data!$A$2:$A$1723,D$1,Data!$B$2:$B$1723,$A8)=0,"",SUMIFS(Data!$F$2:$F$1723,Data!$A$2:$A$1723,D$1,Data!$B$2:$B$1723,$A8)) -> 18487.55 | E8: =IF(COUNTIFS(Data!$A$2:$A$1723,E$1,Data!$B$2:$B$1723,$A8)=0,"",SUMIFS(Data!$F$2:$F$1723,Data!$A$2:$A$1723,E$1,Data!$B$2:$B$1723,$A8)) -> 58385.25 | F8: =IF(COUNTIFS(Data!$A$2:$A$1723,F$1,Data!$B$2:$B$1723,$A8)=0,"",SUMIFS(Data!$F$2:$F$1723,Data!$A$2:$A$1723,F$1,Data!$B$2:$B$1723,$A8)) -> 36090.1 | G8: =IF(COUNTIFS(Data!$A$2:$A$1723,G$1,Data!$B$2:$B$1723,$A8)=0,"",SUMIFS(Data!$F$2:$F$1723,Data!$A$2:$A$1723,G$1,Data!$B$2:$B$1723,$A8)) -> 56615.35 | H8: =IF(COUNTIFS(Data!$A$2:$A$1723,H$1,Data!$B$2:$B$1723,$A8)=0,"",SUMIFS(Data!$F$2:$F$1723,Data!$A$2:$A$1723,H$1,Data!$B$2:$B$1723,$A8)) -> 26948.9
A9: 45960 | B9: =IF(COUNTIFS(Data!$A$2:$A$1723,B$1,Data!$B$2:$B$1723,$A9)=0,"",SUMIFS(Data!$F$2:$F$1723,Data!$A$2:$A$1723,B$1,Data!$B$2:$B$1723,$A9)) -> 25877.85 | C9: =IF(COUNTIFS(Data!$A$2:$A$1723,C$1,Data!$B$2:$B$1723,$A9)=0,"",SUMIFS(Data!$F$2:$F$1723,Data!$A$2:$A$1723,C$1,Data!$B$2:$B$1723,$A9)) -> 60096.25 | D9: =IF(COUNTIFS(Data!$A$2:$A$1723,D$1,Data!$B$2:$B$1723,$A9)=0,"",SUMIFS(Data!$F$2:$F$1723,Data!$A$2:$A$1723,D$1,Data!$B$2:$B$1723,$A9)) -> 18469.7 | E9: =IF(COUNTIFS(Data!$A$2:$A$1723,E$1,Data!$B$2:$B$1723,$A9)=0,"",SUMIFS(Data!$F$2:$F$1723,Data!$A$2:$A$1723,E$1,Data!$B$2:$B$1723,$A9)) -> 58031.1 | F9: =IF(COUNTIFS(Data!$A$2:$A$1723,F$1,Data!$B$2:$B$1723,$A9)=0,"",SUMIFS(Data!$F$2:$F$1723,Data!$A$2:$A$1723,F$1,Data!$B$2:$B$1723,$A9)) -> 35906.4 | G9: =IF(COUNTIFS(Data!$A$2:$A$1723,G$1,Data!$B$2:$B$1723,$A9)=0,"",SUMIFS(Data!$F$2:$F$1723,Data!$A$2:$A$1723,G$1,Data!$B$2:$B$1723,$A9)) -> 56343.5 | H9: =IF(COUNTIFS(Data!$A$2:$A$1723,H$1,Data!$B$2:$B$1723,$A9)=0,"",SUMIFS(Data!$F$2:$F$1723,Data!$A$2:$A$1723,H$1,Data!$B$2:$B$1723,$A9)) -> 26829.55
A10: 45961 | B10: =IF(COUNTIFS(Data!$A$2:$A$1723,B$1,Data!$B$2:$B$1723,$A10)=0,"",SUMIFS(Data!$F$2:$F$1723,Data!$A$2:$A$1723,B$1,Data!$B$2:$B$1723,$A10)) -> 25722.1 | C10: =IF(COUNTIFS(Data!$A$2:$A$1723,C$1,Data!$B$2:$B$1723,$A10)=0,"",SUMIFS(Data!$F$2:$F$1723,Data!$A$2:$A$1723,C$1,Data!$B$2:$B$1723,$A10)) -> 59825.9 | D10: =IF(COUNTIFS(Data!$A$2:$A$1723,D$1,Data!$B$2:$B$1723,$A10)=0,"",SUMIFS(Data!$F$2:$F$1723,Data!$A$2:$A$1723,D$1,Data!$B$2:$B$1723,$A10)) -> 18380.8 | E10: =IF(COUNTIFS(Data!$A$2:$A$1723,E$1,Data!$B$2:$B$1723,$A10)=0,"",SUMIFS(Data!$F$2:$F$1723,Data!$A$2:$A$1723,E$1,Data!$B$2:$B$1723,$A10)) -> 57776.35 | F10: =IF(COUNTIFS(Data!$A$2:$A$1723,F$1,Data!$B$2:$B$1723,$A10)=0,"",SUMIFS(Data!$F$2:$F$1723,Data!$A$2:$A$1723,F$1,Data!$B$2:$B$1723,$A10)) -> 35712.35 | G10: =IF(COUNTIFS(Data!$A$2:$A$1723,G$1,Data!$B$2:$B$1723,$A10)=0,"",SUMIFS(Data!$F$2:$F$1723,Data!$A$2:$A$1723,G$1,Data!$B$2:$B$1723,$A10)) -> 56208.5 | H10: =IF(COUNTIFS(Data!$A$2:$A$1723,H$1,Data!$B$2:$B$1723,$A10)=0,"",SUMIFS(Data!$F$2:$F$1723,Data!$A$2:$A$1723,H$1,Data!$B$2:$B$1723,$A10)) -> 26809.85
A11: 45964 | B11: =IF(COUNTIFS(Data!$A$2:$A$1723,B$1,Data!$B$2:$B$1723,$A11)=0,"",SUMIFS(Data!$F$2:$F$1723,Data!$A$2:$A$1723,B$1,Data!$B$2:$B$1723,$A11)) -> 25763.35 | C11: =IF(COUNTIFS(Data!$A$2:$A$1723,C$1,Data!$B$2:$B$1723,$A11)=0,"",SUMIFS(Data!$F$2:$F$1723,Data!$A$2:$A$1723,C$1,Data!$B$2:$B$1723,$A11)) -> 60287.4 | D11: =IF(COUNTIFS(Data!$A$2:$A$1723,D$1,Data!$B$2:$B$1723,$A11)=0,"",SUMIFS(Data!$F$2:$F$1723,Data!$A$2:$A$1723,D$1,Data!$B$2:$B$1723,$A11)) -> 18513.4 | E11: =IF(COUNTIFS(Data!$A$2:$A$1723,E$1,Data!$B$2:$B$1723,$A11)=0,"",SUMIFS(Data!$F$2:$F$1723,Data!$A$2:$A$1723,E$1,Data!$B$2:$B$1723,$A11)) -> 58101.45 | F11: =IF(COUNTIFS(Data!$A$2:$A$1723,F$1,Data!$B$2:$B$1723,$A11)=0,"",SUMIFS(Data!$F$2:$F$1723,Data!$A$2:$A$1723,F$1,Data!$B$2:$B$1723,$A11)) -> 35653.05 | G11: =IF(COUNTIFS(Data!$A$2:$A$1723,G$1,Data!$B$2:$B$1723,$A11)=0,"",SUMIFS(Data!$F$2:$F$1723,Data!$A$2:$A$1723,G$1,Data!$B$2:$B$1723,$A11)) -> 56153.7 | H11: =IF(COUNTIFS(Data!$A$2:$A$1723,H$1,Data!$B$2:$B$1723,$A11)=0,"",SUMIFS(Data!$F$2:$F$1723,Data!$A$2:$A$1723,H$1,Data!$B$2:$B$1723,$A11)) -> 26841.8
A12: 45965 | B12: =IF(COUNTIFS(Data!$A$2:$A$1723,B$1,Data!$B$2:$B$1723,$A12)=0,"",SUMIFS(Data!$F$2:$F$1723,Data!$A$2:$A$1723,B$1,Data!$B$2:$B$1723,$A12)) -> 25597.65 | C12: =IF(COUNTIFS(Data!$A$2:$A$1723,C$1,Data!$B$2:$B$1723,$A12)=0,"",SUMIFS(Data!$F$2:$F$1723,Data!$A$2:$A$1723,C$1,Data!$B$2:$B$1723,$A12)) -> 60037.2 | D12: =IF(COUNTIFS(Data!$A$2:$A$1723,D$1,Data!$B$2:$B$1723,$A12)=0,"",SUMIFS(Data!$F$2:$F$1723,Data!$A$2:$A$1723,D$1,Data!$B$2:$B$1723,$A12)) -> 18360.9 | E12: =IF(COUNTIFS(Data!$A$2:$A$1723,E$1,Data!$B$2:$B$1723,$A12)=0,"",SUMIFS(Data!$F$2:$F$1723,Data!$A$2:$A$1723,E$1,Data!$B$2:$B$1723,$A12)) -> 57827.05 | F12: =IF(COUNTIFS(Data!$A$2:$A$1723,F$1,Data!$B$2:$B$1723,$A12)=0,"",SUMIFS(Data!$F$2:$F$1723,Data!$A$2:$A$1723,F$1,Data!$B$2:$B$1723,$A12)) -> 35274.55 | G12: =IF(COUNTIFS(Data!$A$2:$A$1723,G$1,Data!$B$2:$B$1723,$A12)=0,"",SUMIFS(Data!$F$2:$F$1723,Data!$A$2:$A$1723,G$1,Data!$B$2:$B$1723,$A12)) -> 55815.6 | H12: =IF(COUNTIFS(Data!$A$2:$A$1723,H$1,Data!$B$2:$B$1723,$A12)=0,"",SUMIFS(Data!$F$2:$F$1723,Data!$A$2:$A$1723,H$1,Data!$B$2:$B$1723,$A12)) -> 26610.05
A13: 45967 | B13: =IF(COUNTIFS(Data!$A$2:$A$1723,B$1,Data!$B$2:$B$1723,$A13)=0,"",SUMIFS(Data!$F$2:$F$1723,Data!$A$2:$A$1723,B$1,Data!$B$2:$B$1723,$A13)) -> 25509.7 | C13: =IF(COUNTIFS(Data!$A$2:$A$1723,C$1,Data!$B$2:$B$1723,$A13)=0,"",SUMIFS(Data!$F$2:$F$1723,Data!$A$2:$A$1723,C$1,Data!$B$2:$B$1723,$A13)) -> 59468.6 | D13: =IF(COUNTIFS(Data!$A$2:$A$1723,D$1,Data!$B$2:$B$1723,$A13)=0,"",SUMIFS(Data!$F$2:$F$1723,Data!$A$2:$A$1723,D$1,Data!$B$2:$B$1723,$A13)) -> 18105 | E13: =IF(COUNTIFS(Data!$A$2:$A$1723,E$1,Data!$B$2:$B$1723,$A13)=0,"",SUMIFS(Data!$F$2:$F$1723,Data!$A$2:$A$1723,E$1,Data!$B$2:$B$1723,$A13)) -> 57554.25 | F13: =IF(COUNTIFS(Data!$A$2:$A$1723,F$1,Data!$B$2:$B$1723,$A13)=0,"",SUMIFS(Data!$F$2:$F$1723,Data!$A$2:$A$1723,F$1,Data!$B$2:$B$1723,$A13)) -> 35337.6 | G13: =IF(COUNTIFS(Data!$A$2:$A$1723,G$1,Data!$B$2:$B$1723,$A13)=0,"",SUMIFS(Data!$F$2:$F$1723,Data!$A$2:$A$1723,G$1,Data!$B$2:$B$1723,$A13)) -> 55711.75 | H13: =IF(COUNTIFS(Data!$A$2:$A$1723,H$1,Data!$B$2:$B$1723,$A13)=0,"",SUMIFS(Data!$F$2:$F$1723,Data!$A$2:$A$1723,H$1,Data!$B$2:$B$1723,$A13)) -> 26626.5
... A247: 46311 | B247: =IF(COUNTIFS(Data!$A$2:$A$1723,B$1,Data!$B$2:$B$1723,$A247)=0,"",SUMIFS(Data!$F$2:$F$1723,Data!$A$2:$A$1723,B$1,Data!$B$2:$B$1723,$A247)) -> 23146.15 | C247: =IF(COUNTIFS(Data!$A$2:$A$1723,C$1,Data!$B$2:$B$1723,$A247)=0,"",SUMIFS(Data!$F$2:$F$1723,Data!$A$2:$A$1723,C$1,Data!$B$2:$B$1723,$A247)) -> 59129.75 | D247: =IF(COUNTIFS(Data!$A$2:$A$1723,D$1,Data!$B$2:$B$1723,$A247)=0,"",SUMIFS(Data!$F$2:$F$1723,Data!$A$2:$A$1723,D$1,Data!$B$2:$B$1723,$A247)) -> 19129.8 | E247: =IF(COUNTIFS(Data!$A$2:$A$1723,E$1,Data!$B$2:$B$1723,$A247)=0,"",SUMIFS(Data!$F$2:$F$1723,Data!$A$2:$A$1723,E$1,Data!$B$2:$B$1723,$A247)) -> 55844 | F247: =IF(COUNTIFS(Data!$A$2:$A$1723,F$1,Data!$B$2:$B$1723,$A247)=0,"",SUMIFS(Data!$F$2:$F$1723,Data!$A$2:$A$1723,F$1,Data!$B$2:$B$1723,$A247)) -> 31924.1 | G247: =IF(COUNTIFS(Data!$A$2:$A$1723,G$1,Data!$B$2:$B$1723,$A247)=0,"",SUMIFS(Data!$F$2:$F$1723,Data!$A$2:$A$1723,G$1,Data!$B$2:$B$1723,$A247)) -> 44616.15 | H247: =IF(COUNTIFS(Data!$A$2:$A$1723,H$1,Data!$B$2:$B$1723,$A247)=0,"",SUMIFS(Data!$F$2:$F$1723,Data!$A$2:$A$1723,H$1,Data!$B$2:$B$1723,$A247)) -> 25768.5

Sheet Returns
A1: Returns by index
A3: Index | B3: 1 Week | C3: 1 Month | D3: 3 Months | E3: Rebound (since rebound start) | F3: 1 Year (full data)
A4: =Prices!B1 -> NIFTY 50 | B4: =INDEX(Prices!$B$2:$H$247,Inputs!$B$12,MATCH($A4,Prices!$B$1:$H$1,0))/INDEX(Prices!$B$2:$H$247,Inputs!$B$12-Inputs!$B$9,MATCH($A4,Prices!$B$1:$H$1,0))-1 -> 0.027783637 | C4: =INDEX(Prices!$B$2:$H$247,Inputs!$B$12,MATCH($A4,Prices!$B$1:$H$1,0))/INDEX(Prices!$B$2:$H$247,Inputs!$B$12-Inputs!$B$10,MATCH($A4,Prices!$B$1:$H$1,0))-1 -> -0.0030774068 | D4: =INDEX(Prices!$B$2:$H$247,Inputs!$B$12,MATCH($A4,Prices!$B$1:$H$1,0))/INDEX(Prices!$B$2:$H$247,Inputs!$B$12-Inputs!$B$11,MATCH($A4,Prices!$B$1:$H$1,0))-1 -> -0.048826143 | E4: =INDEX(Prices!$B$2:$H$247,Inputs!$B$12,MATCH($A4,Prices!$B$1:$H$1,0))/INDEX(Prices!$B$2:$H$247,Inputs!$B$14,MATCH($A4,Prices!$B$1:$H$1,0))-1 -> 0.041128024 | F4: =INDEX(Prices!$B$2:$H$247,Inputs!$B$12,MATCH($A4,Prices!$B$1:$H$1,0))/INDEX(Prices!$B$2:$H$247,1,MATCH($A4,Prices!$B$1:$H$1,0))-1 -> -0.10436034
A5: =Prices!C1 -> NIFTY MIDCAP 100 | B5: =INDEX(Prices!$B$2:$H$247,Inputs!$B$12,MATCH($A5,Prices!$B$1:$H$1,0))/INDEX(Prices!$B$2:$H$247,Inputs!$B$12-Inputs!$B$9,MATCH($A5,Prices!$B$1:$H$1,0))-1 -> 0.0058252378 | C5: =INDEX(Prices!$B$2:$H$247,Inputs!$B$12,MATCH($A5,Prices!$B$1:$H$1,0))/INDEX(Prices!$B$2:$H$247,Inputs!$B$12-Inputs!$B$10,MATCH($A5,Prices!$B$1:$H$1,0))-1 -> -0.028656639 | D5: =INDEX(Prices!$B$2:$H$247,Inputs!$B$12,MATCH($A5,Prices!$B$1:$H$1,0))/INDEX(Prices!$B$2:$H$247,Inputs!$B$12-Inputs!$B$11,MATCH($A5,Prices!$B$1:$H$1,0))-1 -> -0.052833622 | E5: =INDEX(Prices!$B$2:$H$247,Inputs!$B$12,MATCH($A5,Prices!$B$1:$H$1,0))/INDEX(Prices!$B$2:$H$247,Inputs!$B$14,MATCH($A5,Prices!$B$1:$H$1,0))-1 -> 0.021547964 | F5: =INDEX(Prices!$B$2:$H$247,Inputs!$B$12,MATCH($A5,Prices!$B$1:$H$1,0))/INDEX(Prices!$B$2:$H$247,1,MATCH($A5,Prices!$B$1:$H$1,0))-1 -> -0.003618701
A6: =Prices!D1 -> NIFTY SMALLCAP 100 | B6: =INDEX(Prices!$B$2:$H$247,Inputs!$B$12,MATCH($A6,Prices!$B$1:$H$1,0))/INDEX(Prices!$B$2:$H$247,Inputs!$B$12-Inputs!$B$9,MATCH($A6,Prices!$B$1:$H$1,0))-1 -> -0.0012478007 | C6: =INDEX(Prices!$B$2:$H$247,Inputs!$B$12,MATCH($A6,Prices!$B$1:$H$1,0))/INDEX(Prices!$B$2:$H$247,Inputs!$B$12-Inputs!$B$10,MATCH($A6,Prices!$B$1:$H$1,0))-1 -> -0.013332783 | D6: =INDEX(Prices!$B$2:$H$247,Inputs!$B$12,MATCH($A6,Prices!$B$1:$H$1,0))/INDEX(Prices!$B$2:$H$247,Inputs!$B$12-Inputs!$B$11,MATCH($A6,Prices!$B$1:$H$1,0))-1 -> -0.0086285972 | E6: =INDEX(Prices!$B$2:$H$247,Inputs!$B$12,MATCH($A6,Prices!$B$1:$H$1,0))/INDEX(Prices!$B$2:$H$247,Inputs!$B$14,MATCH($A6,Prices!$B$1:$H$1,0))-1 -> 0.0041837051 | F6: =INDEX(Prices!$B$2:$H$247,Inputs!$B$12,MATCH($A6,Prices!$B$1:$H$1,0))/INDEX(Prices!$B$2:$H$247,1,MATCH($A6,Prices!$B$1:$H$1,0))-1 -> 0.050732857
A7: =Prices!E1 -> NIFTY BANK | B7: =INDEX(Prices!$B$2:$H$247,Inputs!$B$12,MATCH($A7,Prices!$B$1:$H$1,0))/INDEX(Prices!$B$2:$H$247,Inputs!$B$12-Inputs!$B$9,MATCH($A7,Prices!$B$1:$H$1,0))-1 -> 0.01062949 | C7: =INDEX(Prices!$B$2:$H$247,Inputs!$B$12,MATCH($A7,Prices!$B$1:$H$1,0))/INDEX(Prices!$B$2:$H$247,Inputs!$B$12-Inputs!$B$10,MATCH($A7,Prices!$B$1:$H$1,0))-1 -> -0.0079664324 | D7: =INDEX(Prices!$B$2:$H$247,Inputs!$B$12,MATCH($A7,Prices!$B$1:$H$1,0))/INDEX(Prices!$B$2:$H$247,Inputs!$B$12-Inputs!$B$11,MATCH($A7,Prices!$B$1:$H$1,0))-1 -> -0.045750785 | E7: =INDEX(Prices!$B$2:$H$247,Inputs!$B$12,MATCH($A7,Prices!$B$1:$H$1,0))/INDEX(Prices!$B$2:$H$247,Inputs!$B$14,MATCH($A7,Prices!$B$1:$H$1,0))-1 -> 0.024377672 | F7: =INDEX(Prices!$B$2:$H$247,Inputs!$B$12,MATCH($A7,Prices!$B$1:$H$1,0))/INDEX(Prices!$B$2:$H$247,1,MATCH($A7,Prices!$B$1:$H$1,0))-1 -> -0.037723234
A8: =Prices!F1 -> NIFTY IT | B8: =INDEX(Prices!$B$2:$H$247,Inputs!$B$12,MATCH($A8,Prices!$B$1:$H$1,0))/INDEX(Prices!$B$2:$H$247,Inputs!$B$12-Inputs!$B$9,MATCH($A8,Prices!$B$1:$H$1,0))-1 -> 0.11720776 | C8: =INDEX(Prices!$B$2:$H$247,Inputs!$B$12,MATCH($A8,Prices!$B$1:$H$1,0))/INDEX(Prices!$B$2:$H$247,Inputs!$B$12-Inputs!$B$10,MATCH($A8,Prices!$B$1:$H$1,0))-1 -> 0.097513893 | D8: =INDEX(Prices!$B$2:$H$247,Inputs!$B$12,MATCH($A8,Prices!$B$1:$H$1,0))/INDEX(Prices!$B$2:$H$247,Inputs!$B$12-Inputs!$B$11,MATCH($A8,Prices!$B$1:$H$1,0))-1 -> 0.092296059 | E8: =INDEX(Prices!$B$2:$H$247,Inputs!$B$12,MATCH($A8,Prices!$B$1:$H$1,0))/INDEX(Prices!$B$2:$H$247,Inputs!$B$14,MATCH($A8,Prices!$B$1:$H$1,0))-1 -> 0.1509738 | F8: =INDEX(Prices!$B$2:$H$247,Inputs!$B$12,MATCH($A8,Prices!$B$1:$H$1,0))/INDEX(Prices!$B$2:$H$247,1,MATCH($A8,Prices!$B$1:$H$1,0))-1 -> -0.095444937
A9: =Prices!G1 -> NIFTY FMCG | B9: =INDEX(Prices!$B$2:$H$247,Inputs!$B$12,MATCH($A9,Prices!$B$1:$H$1,0))/INDEX(Prices!$B$2:$H$247,Inputs!$B$12-Inputs!$B$9,MATCH($A9,Prices!$B$1:$H$1,0))-1 -> -0.0055300155 | C9: =INDEX(Prices!$B$2:$H$247,Inputs!$B$12,MATCH($A9,Prices!$B$1:$H$1,0))/INDEX(Prices!$B$2:$H$247,Inputs!$B$12-Inputs!$B$10,MATCH($A9,Prices!$B$1:$H$1,0))-1 -> -0.020695143 | D9: =INDEX(Prices!$B$2:$H$247,Inputs!$B$12,MATCH($A9,Prices!$B$1:$H$1,0))/INDEX(Prices!$B$2:$H$247,Inputs!$B$12-Inputs!$B$11,MATCH($A9,Prices!$B$1:$H$1,0))-1 -> -0.084772517 | E9: =INDEX(Prices!$B$2:$H$247,Inputs!$B$12,MATCH($A9,Prices!$B$1:$H$1,0))/INDEX(Prices!$B$2:$H$247,Inputs!$B$14,MATCH($A9,Prices!$B$1:$H$1,0))-1 -> 0.016358358 | F9: =INDEX(Prices!$B$2:$H$247,Inputs!$B$12,MATCH($A9,Prices!$B$1:$H$1,0))/INDEX(Prices!$B$2:$H$247,1,MATCH($A9,Prices!$B$1:$H$1,0))-1 -> -0.2116891
A10: =Prices!H1 -> NIFTY AUTO | B10: =INDEX(Prices!$B$2:$H$247,Inputs!$B$12,MATCH($A10,Prices!$B$1:$H$1,0))/INDEX(Prices!$B$2:$H$247,Inputs!$B$12-Inputs!$B$9,MATCH($A10,Prices!$B$1:$H$1,0))-1 -> 0.03654882 | C10: =INDEX(Prices!$B$2:$H$247,Inputs!$B$12,MATCH($A10,Prices!$B$1:$H$1,0))/INDEX(Prices!$B$2:$H$247,Inputs!$B$12-Inputs!$B$10,MATCH($A10,Prices!$B$1:$H$1,0))-1 -> -0.041837014 | D10: =INDEX(Prices!$B$2:$H$247,Inputs!$B$12,MATCH($A10,Prices!$B$1:$H$1,0))/INDEX(Prices!$B$2:$H$247,Inputs!$B$12-Inputs!$B$11,MATCH($A10,Prices!$B$1:$H$1,0))-1 -> -0.049124069 | E10: =INDEX(Prices!$B$2:$H$247,Inputs!$B$12,MATCH($A10,Prices!$B$1:$H$1,0))/INDEX(Prices!$B$2:$H$247,Inputs!$B$14,MATCH($A10,Prices!$B$1:$H$1,0))-1 -> 0.051230587 | F10: =INDEX(Prices!$B$2:$H$247,Inputs!$B$12,MATCH($A10,Prices!$B$1:$H$1,0))/INDEX(Prices!$B$2:$H$247,1,MATCH($A10,Prices!$B$1:$H$1,0))-1 -> -0.052121631
A13: Spreads (percentage points, Nifty 50 minus the other index)
A14: Comparison | B14: 1 Week | C14: 1 Month | D14: 3 Months | E14: Rebound | F14: Reading (rebound)
A15: Nifty 50 minus Midcap 100 | B15: =B4-B5 -> 0.021958399 | C15: =C4-C5 -> 0.025579233 | D15: =D4-D5 -> 0.0040074795 | E15: =E4-E5 -> 0.01958006 | F15: =IF(E15>Inputs!$B$15,"Large caps lead (narrow)",IF(E15>Inputs!$B$15/2,"Large caps slightly ahead",IF(E15<-Inputs!$B$15,"Smaller caps lead (broad)",IF(E15<-Inputs!$B$15/2,"Smaller caps slightly ahead","In line")))) -> Large caps slightly ahead
A16: Nifty 50 minus Smallcap 100 | B16: =B4-B6 -> 0.029031437 | C16: =C4-C6 -> 0.010255376 | D16: =D4-D6 -> -0.040197545 | E16: =E4-E6 -> 0.036944319 | F16: =IF(E16>Inputs!$B$15,"Large caps lead (narrow)",IF(E16>Inputs!$B$15/2,"Large caps slightly ahead",IF(E16<-Inputs!$B$15,"Smaller caps lead (broad)",IF(E16<-Inputs!$B$15/2,"Smaller caps slightly ahead","In line")))) -> Large caps lead (narrow)
A18: Reading rule: above the threshold = clear signal. Between half the threshold and the threshold = slightly ahead (borderline). Below half = in line. Judge it together with the other tabs.

Sheet Rebased
A1: Date | B1: NIFTY 50 | C1: NIFTY Midcap 100 | D1: NIFTY Smallcap 100 | E1: NIFTY Bank | F1: NIFTY IT | G1: NIFTY FMCG | H1: NIFTY Auto
A2: =INDEX(Prices!$A$2:$A$247,Inputs!$B$13+ROW()-2) -> 46219 | B2: =INDEX(Prices!B$2:B$247,Inputs!$B$13+ROW()-2)/INDEX(Prices!B$2:B$247,Inputs!$B$13)*100 -> 100 | C2: =INDEX(Prices!C$2:C$247,Inputs!$B$13+ROW()-2)/INDEX(Prices!C$2:C$247,Inputs!$B$13)*100 -> 100 | D2: =INDEX(Prices!D$2:D$247,Inputs!$B$13+ROW()-2)/INDEX(Prices!D$2:D$247,Inputs!$B$13)*100 -> 100 | E2: =INDEX(Prices!E$2:E$247,Inputs!$B$13+ROW()-2)/INDEX(Prices!E$2:E$247,Inputs!$B$13)*100 -> 100 | F2: =INDEX(Prices!F$2:F$247,Inputs!$B$13+ROW()-2)/INDEX(Prices!F$2:F$247,Inputs!$B$13)*100 -> 100 | G2: =INDEX(Prices!G$2:G$247,Inputs!$B$13+ROW()-2)/INDEX(Prices!G$2:G$247,Inputs!$B$13)*100 -> 100 | H2: =INDEX(Prices!H$2:H$247,Inputs!$B$13+ROW()-2)/INDEX(Prices!H$2:H$247,Inputs!$B$13)*100 -> 100
A3: =INDEX(Prices!$A$2:$A$247,Inputs!$B$13+ROW()-2) -> 46220 | B3: =INDEX(Prices!B$2:B$247,Inputs!$B$13+ROW()-2)/INDEX(Prices!B$2:B$247,Inputs!$B$13)*100 -> 101.0865 | C3: =INDEX(Prices!C$2:C$247,Inputs!$B$13+ROW()-2)/INDEX(Prices!C$2:C$247,Inputs!$B$13)*100 -> 99.587313 | D3: =INDEX(Prices!D$2:D$247,Inputs!$B$13+ROW()-2)/INDEX(Prices!D$2:D$247,Inputs!$B$13)*100 -> 99.793393 | E3: =INDEX(Prices!E$2:E$247,Inputs!$B$13+ROW()-2)/INDEX(Prices!E$2:E$247,Inputs!$B$13)*100 -> 101.63097 | F3: =INDEX(Prices!F$2:F$247,Inputs!$B$13+ROW()-2)/INDEX(Prices!F$2:F$247,Inputs!$B$13)*100 -> 101.75472 | G3: =INDEX(Prices!G$2:G$247,Inputs!$B$13+ROW()-2)/INDEX(Prices!G$2:G$247,Inputs!$B$13)*100 -> 100.70381 | H3: =INDEX(Prices!H$2:H$247,Inputs!$B$13+ROW()-2)/INDEX(Prices!H$2:H$247,Inputs!$B$13)*100 -> 101.24105
A4: =INDEX(Prices!$A$2:$A$247,Inputs!$B$13+ROW()-2) -> 46223 | B4: =INDEX(Prices!B$2:B$247,Inputs!$B$13+ROW()-2)/INDEX(Prices!B$2:B$247,Inputs!$B$13)*100 -> 100.68854 | C4: =INDEX(Prices!C$2:C$247,Inputs!$B$13+ROW()-2)/INDEX(Prices!C$2:C$247,Inputs!$B$13)*100 -> 100.18345 | D4: =INDEX(Prices!D$2:D$247,Inputs!$B$13+ROW()-2)/INDEX(Prices!D$2:D$247,Inputs!$B$13)*100 -> 99.949318 | E4: =INDEX(Prices!E$2:E$247,Inputs!$B$13+ROW()-2)/INDEX(Prices!E$2:E$247,Inputs!$B$13)*100 -> 100.62997 | F4: =INDEX(Prices!F$2:F$247,Inputs!$B$13+ROW()-2)/INDEX(Prices!F$2:F$247,Inputs!$B$13)*100 -> 101.52928 | G4: =INDEX(Prices!G$2:G$247,Inputs!$B$13+ROW()-2)/INDEX(Prices!G$2:G$247,Inputs!$B$13)*100 -> 101.36227 | H4: =INDEX(Prices!H$2:H$247,Inputs!$B$13+ROW()-2)/INDEX(Prices!H$2:H$247,Inputs!$B$13)*100 -> 100.97431
A5: =INDEX(Prices!$A$2:$A$247,Inputs!$B$13+ROW()-2) -> 46224 | B5: =INDEX(Prices!B$2:B$247,Inputs!$B$13+ROW()-2)/INDEX(Prices!B$2:B$247,Inputs!$B$13)*100 -> 100.47751 | C5: =INDEX(Prices!C$2:C$247,Inputs!$B$13+ROW()-2)/INDEX(Prices!C$2:C$247,Inputs!$B$13)*100 -> 100.47993 | D5: =INDEX(Prices!D$2:D$247,Inputs!$B$13+ROW()-2)/INDEX(Prices!D$2:D$247,Inputs!$B$13)*100 -> 100.47476 | E5: =INDEX(Prices!E$2:E$247,Inputs!$B$13+ROW()-2)/INDEX(Prices!E$2:E$247,Inputs!$B$13)*100 -> 100.43955 | F5: =INDEX(Prices!F$2:F$247,Inputs!$B$13+ROW()-2)/INDEX(Prices!F$2:F$247,Inputs!$B$13)*100 -> 100.91148 | G5: =INDEX(Prices!G$2:G$247,Inputs!$B$13+ROW()-2)/INDEX(Prices!G$2:G$247,Inputs!$B$13)*100 -> 101.05189 | H5: =INDEX(Prices!H$2:H$247,Inputs!$B$13+ROW()-2)/INDEX(Prices!H$2:H$247,Inputs!$B$13)*100 -> 101.91669
A6: =INDEX(Prices!$A$2:$A$247,Inputs!$B$13+ROW()-2) -> 46225 | B6: =INDEX(Prices!B$2:B$247,Inputs!$B$13+ROW()-2)/INDEX(Prices!B$2:B$247,Inputs!$B$13)*100 -> 99.682213 | C6: =INDEX(Prices!C$2:C$247,Inputs!$B$13+ROW()-2)/INDEX(Prices!C$2:C$247,Inputs!$B$13)*100 -> 99.384001 | D6: =INDEX(Prices!D$2:D$247,Inputs!$B$13+ROW()-2)/INDEX(Prices!D$2:D$247,Inputs!$B$13)*100 -> 98.929472 | E6: =INDEX(Prices!E$2:E$247,Inputs!$B$13+ROW()-2)/INDEX(Prices!E$2:E$247,Inputs!$B$13)*100 -> 99.209044 | F6: =INDEX(Prices!F$2:F$247,Inputs!$B$13+ROW()-2)/INDEX(Prices!F$2:F$247,Inputs!$B$13)*100 -> 99.398557 | G6: =INDEX(Prices!G$2:G$247,Inputs!$B$13+ROW()-2)/INDEX(Prices!G$2:G$247,Inputs!$B$13)*100 -> 101.70592 | H6: =INDEX(Prices!H$2:H$247,Inputs!$B$13+ROW()-2)/INDEX(Prices!H$2:H$247,Inputs!$B$13)*100 -> 102.09993
A7: =INDEX(Prices!$A$2:$A$247,Inputs!$B$13+ROW()-2) -> 46226 | B7: =INDEX(Prices!B$2:B$247,Inputs!$B$13+ROW()-2)/INDEX(Prices!B$2:B$247,Inputs!$B$13)*100 -> 99.1561 | C7: =INDEX(Prices!C$2:C$247,Inputs!$B$13+ROW()-2)/INDEX(Prices!C$2:C$247,Inputs!$B$13)*100 -> 98.401975 | D7: =INDEX(Prices!D$2:D$247,Inputs!$B$13+ROW()-2)/INDEX(Prices!D$2:D$247,Inputs!$B$13)*100 -> 97.931864 | E7: =INDEX(Prices!E$2:E$247,Inputs!$B$13+ROW()-2)/INDEX(Prices!E$2:E$247,Inputs!$B$13)*100 -> 98.280286 | F7: =INDEX(Prices!F$2:F$247,Inputs!$B$13+ROW()-2)/INDEX(Prices!F$2:F$247,Inputs!$B$13)*100 -> 99.341807 | G7: =INDEX(Prices!G$2:G$247,Inputs!$B$13+ROW()-2)/INDEX(Prices!G$2:G$247,Inputs!$B$13)*100 -> 101.29152 | H7: =INDEX(Prices!H$2:H$247,Inputs!$B$13+ROW()-2)/INDEX(Prices!H$2:H$247,Inputs!$B$13)*100 -> 102.81404
A8: =INDEX(Prices!$A$2:$A$247,Inputs!$B$13+ROW()-2) -> 46227 | B8: =INDEX(Prices!B$2:B$247,Inputs!$B$13+ROW()-2)/INDEX(Prices!B$2:B$247,Inputs!$B$13)*100 -> 98.731761 | C8: =INDEX(Prices!C$2:C$247,Inputs!$B$13+ROW()-2)/INDEX(Prices!C$2:C$247,Inputs!$B$13)*100 -> 98.302034 | D8: =INDEX(Prices!D$2:D$247,Inputs!$B$13+ROW()-2)/INDEX(Prices!D$2:D$247,Inputs!$B$13)*100 -> 97.614325 | E8: =INDEX(Prices!E$2:E$247,Inputs!$B$13+ROW()-2)/INDEX(Prices!E$2:E$247,Inputs!$B$13)*100 -> 98.456556 | F8: =INDEX(Prices!F$2:F$247,Inputs!$B$13+ROW()-2)/INDEX(Prices!F$2:F$247,Inputs!$B$13)*100 -> 100.15789 | G8: =INDEX(Prices!G$2:G$247,Inputs!$B$13+ROW()-2)/INDEX(Prices!G$2:G$247,Inputs!$B$13)*100 -> 101.33304 | H8: =INDEX(Prices!H$2:H$247,Inputs!$B$13+ROW()-2)/INDEX(Prices!H$2:H$247,Inputs!$B$13)*100 -> 101.68263
A9: =INDEX(Prices!$A$2:$A$247,Inputs!$B$13+ROW()-2) -> 46230 | B9: =INDEX(Prices!B$2:B$247,Inputs!$B$13+ROW()-2)/INDEX(Prices!B$2:B$247,Inputs!$B$13)*100 -> 99.680967 | C9: =INDEX(Prices!C$2:C$247,Inputs!$B$13+ROW()-2)/INDEX(Prices!C$2:C$247,Inputs!$B$13)*100 -> 99.388866 | D9: =INDEX(Prices!D$2:D$247,Inputs!$B$13+ROW()-2)/INDEX(Prices!D$2:D$247,Inputs!$B$13)*100 -> 98.89508 | E9: =INDEX(Prices!E$2:E$247,Inputs!$B$13+ROW()-2)/INDEX(Prices!E$2:E$247,Inputs!$B$13)*100 -> 99.140273 | F9: =INDEX(Prices!F$2:F$247,Inputs!$B$13+ROW()-2)/INDEX(Prices!F$2:F$247,Inputs!$B$13)*100 -> 102.5043 | G9: =INDEX(Prices!G$2:G$247,Inputs!$B$13+ROW()-2)/INDEX(Prices!G$2:G$247,Inputs!$B$13)*100 -> 102.38969 | H9: =INDEX(Prices!H$2:H$247,Inputs!$B$13+ROW()-2)/INDEX(Prices!H$2:H$247,Inputs!$B$13)*100 -> 103.30942
A10: =INDEX(Prices!$A$2:$A$247,Inputs!$B$13+ROW()-2) -> 46231 | B10: =INDEX(Prices!B$2:B$247,Inputs!$B$13+ROW()-2)/INDEX(Prices!B$2:B$247,Inputs!$B$13)*100 -> 99.636934 | C10: =INDEX(Prices!C$2:C$247,Inputs!$B$13+ROW()-2)/INDEX(Prices!C$2:C$247,Inputs!$B$13)*100 -> 99.465198 | D10: =INDEX(Prices!D$2:D$247,Inputs!$B$13+ROW()-2)/INDEX(Prices!D$2:D$247,Inputs!$B$13)*100 -> 98.678389 | E10: =INDEX(Prices!E$2:E$247,Inputs!$B$13+ROW()-2)/INDEX(Prices!E$2:E$247,Inputs!$B$13)*100 -> 98.564401 | F10: =INDEX(Prices!F$2:F$247,Inputs!$B$13+ROW()-2)/INDEX(Prices!F$2:F$247,Inputs!$B$13)*100 -> 105.90389 | G10: =INDEX(Prices!G$2:G$247,Inputs!$B$13+ROW()-2)/INDEX(Prices!G$2:G$247,Inputs!$B$13)*100 -> 100.97752 | H10: =INDEX(Prices!H$2:H$247,Inputs!$B$13+ROW()-2)/INDEX(Prices!H$2:H$247,Inputs!$B$13)*100 -> 104.0211
A11: =INDEX(Prices!$A$2:$A$247,Inputs!$B$13+ROW()-2) -> 46232 | B11: =INDEX(Prices!B$2:B$247,Inputs!$B$13+ROW()-2)/INDEX(Prices!B$2:B$247,Inputs!$B$13)*100 -> 100.73714 | C11: =INDEX(Prices!C$2:C$247,Inputs!$B$13+ROW()-2)/INDEX(Prices!C$2:C$247,Inputs!$B$13)*100 -> 100.27996 | D11: =INDEX(Prices!D$2:D$247,Inputs!$B$13+ROW()-2)/INDEX(Prices!D$2:D$247,Inputs!$B$13)*100 -> 100.13498 | E11: =INDEX(Prices!E$2:E$247,Inputs!$B$13+ROW()-2)/INDEX(Prices!E$2:E$247,Inputs!$B$13)*100 -> 99.346413 | F11: =INDEX(Prices!F$2:F$247,Inputs!$B$13+ROW()-2)/INDEX(Prices!F$2:F$247,Inputs!$B$13)*100 -> 108.35753 | G11: =INDEX(Prices!G$2:G$247,Inputs!$B$13+ROW()-2)/INDEX(Prices!G$2:G$247,Inputs!$B$13)*100 -> 102.64967 | H11: =INDEX(Prices!H$2:H$247,Inputs!$B$13+ROW()-2)/INDEX(Prices!H$2:H$247,Inputs!$B$13)*100 -> 103.95404
A12: =INDEX(Prices!$A$2:$A$247,Inputs!$B$13+ROW()-2) -> 46233 | B12: =INDEX(Prices!B$2:B$247,Inputs!$B$13+ROW()-2)/INDEX(Prices!B$2:B$247,Inputs!$B$13)*100 -> 101.01526 | C12: =INDEX(Prices!C$2:C$247,Inputs!$B$13+ROW()-2)/INDEX(Prices!C$2:C$247,Inputs!$B$13)*100 -> 99.928214 | D12: =INDEX(Prices!D$2:D$247,Inputs!$B$13+ROW()-2)/INDEX(Prices!D$2:D$247,Inputs!$B$13)*100 -> 99.57696 | E12: =INDEX(Prices!E$2:E$247,Inputs!$B$13+ROW()-2)/INDEX(Prices!E$2:E$247,Inputs!$B$13)*100 -> 99.244993 | F12: =INDEX(Prices!F$2:F$247,Inputs!$B$13+ROW()-2)/INDEX(Prices!F$2:F$247,Inputs!$B$13)*100 -> 108.60629 | G12: =INDEX(Prices!G$2:G$247,Inputs!$B$13+ROW()-2)/INDEX(Prices!G$2:G$247,Inputs!$B$13)*100 -> 102.54927 | H12: =INDEX(Prices!H$2:H$247,Inputs!$B$13+ROW()-2)/INDEX(Prices!H$2:H$247,Inputs!$B$13)*100 -> 105.64695
A13: =INDEX(Prices!$A$2:$A$247,Inputs!$B$13+ROW()-2) -> 46234 | B13: =INDEX(Prices!B$2:B$247,Inputs!$B$13+ROW()-2)/INDEX(Prices!B$2:B$247,Inputs!$B$13)*100 -> 101.29129 | C13: =INDEX(Prices!C$2:C$247,Inputs!$B$13+ROW()-2)/INDEX(Prices!C$2:C$247,Inputs!$B$13)*100 -> 100.36459 | D13: =INDEX(Prices!D$2:D$247,Inputs!$B$13+ROW()-2)/INDEX(Prices!D$2:D$247,Inputs!$B$13)*100 -> 100.01758 | E13: =INDEX(Prices!E$2:E$247,Inputs!$B$13+ROW()-2)/INDEX(Prices!E$2:E$247,Inputs!$B$13)*100 -> 99.448788 | F13: =INDEX(Prices!F$2:F$247,Inputs!$B$13+ROW()-2)/INDEX(Prices!F$2:F$247,Inputs!$B$13)*100 -> 106.91546 | G13: =INDEX(Prices!G$2:G$247,Inputs!$B$13+ROW()-2)/INDEX(Prices!G$2:G$247,Inputs!$B$13)*100 -> 101.47331 | H13: =INDEX(Prices!H$2:H$247,Inputs!$B$13+ROW()-2)/INDEX(Prices!H$2:H$247,Inputs!$B$13)*100 -> 107.38431
... A66: =INDEX(Prices!$A$2:$A$247,Inputs!$B$13+ROW()-2) -> 46311 | B66: =INDEX(Prices!B$2:B$247,Inputs!$B$13+ROW()-2)/INDEX(Prices!B$2:B$247,Inputs!$B$13)*100 -> 96.150834 | C66: =INDEX(Prices!C$2:C$247,Inputs!$B$13+ROW()-2)/INDEX(Prices!C$2:C$247,Inputs!$B$13)*100 -> 94.325755 | D66: =INDEX(Prices!D$2:D$247,Inputs!$B$13+ROW()-2)/INDEX(Prices!D$2:D$247,Inputs!$B$13)*100 -> 98.932316 | E66: =INDEX(Prices!E$2:E$247,Inputs!$B$13+ROW()-2)/INDEX(Prices!E$2:E$247,Inputs!$B$13)*100 -> 96.981275 | F66: =INDEX(Prices!F$2:F$247,Inputs!$B$13+ROW()-2)/INDEX(Prices!F$2:F$247,Inputs!$B$13)*100 -> 111.14628 | G66: =INDEX(Prices!G$2:G$247,Inputs!$B$13+ROW()-2)/INDEX(Prices!G$2:G$247,Inputs!$B$13)*100 -> 92.166894 | H66: =INDEX(Prices!H$2:H$247,Inputs!$B$13+ROW()-2)/INDEX(Prices!H$2:H$247,Inputs!$B$13)*100 -> 96.267682
A68: Rows cover the analysis window (65 trading days). If you change the window dates, the row count must be re-extended.

Sheet Drawdown
A1: Date | B1: NIFTY 50 | C1: NIFTY MIDCAP 100 | D1: NIFTY SMALLCAP 100 | E1: NIFTY BANK | F1: NIFTY IT | G1: NIFTY FMCG | H1: NIFTY AUTO
A2: =INDEX(Prices!$A$2:$A$247,Inputs!$B$13+ROW()-2) -> 46219 | B2: =INDEX(Prices!B$2:B$247,Inputs!$B$13+ROW()-2)/MAX(INDEX(Prices!B$2:B$247,Inputs!$B$13):INDEX(Prices!B$2:B$247,Inputs!$B$13+ROW()-2))-1 -> 0 | C2: =INDEX(Prices!C$2:C$247,Inputs!$B$13+ROW()-2)/MAX(INDEX(Prices!C$2:C$247,Inputs!$B$13):INDEX(Prices!C$2:C$247,Inputs!$B$13+ROW()-2))-1 -> 0 | D2: =INDEX(Prices!D$2:D$247,Inputs!$B$13+ROW()-2)/MAX(INDEX(Prices!D$2:D$247,Inputs!$B$13):INDEX(Prices!D$2:D$247,Inputs!$B$13+ROW()-2))-1 -> 0 | E2: =INDEX(Prices!E$2:E$247,Inputs!$B$13+ROW()-2)/MAX(INDEX(Prices!E$2:E$247,Inputs!$B$13):INDEX(Prices!E$2:E$247,Inputs!$B$13+ROW()-2))-1 -> 0 | F2: =INDEX(Prices!F$2:F$247,Inputs!$B$13+ROW()-2)/MAX(INDEX(Prices!F$2:F$247,Inputs!$B$13):INDEX(Prices!F$2:F$247,Inputs!$B$13+ROW()-2))-1 -> 0 | G2: =INDEX(Prices!G$2:G$247,Inputs!$B$13+ROW()-2)/MAX(INDEX(Prices!G$2:G$247,Inputs!$B$13):INDEX(Prices!G$2:G$247,Inputs!$B$13+ROW()-2))-1 -> 0 | H2: =INDEX(Prices!H$2:H$247,Inputs!$B$13+ROW()-2)/MAX(INDEX(Prices!H$2:H$247,Inputs!$B$13):INDEX(Prices!H$2:H$247,Inputs!$B$13+ROW()-2))-1 -> 0
A3: =INDEX(Prices!$A$2:$A$247,Inputs!$B$13+ROW()-2) -> 46220 | B3: =INDEX(Prices!B$2:B$247,Inputs!$B$13+ROW()-2)/MAX(INDEX(Prices!B$2:B$247,Inputs!$B$13):INDEX(Prices!B$2:B$247,Inputs!$B$13+ROW()-2))-1 -> 0 | C3: =INDEX(Prices!C$2:C$247,Inputs!$B$13+ROW()-2)/MAX(INDEX(Prices!C$2:C$247,Inputs!$B$13):INDEX(Prices!C$2:C$247,Inputs!$B$13+ROW()-2))-1 -> -0.0041268689 | D3: =INDEX(Prices!D$2:D$247,Inputs!$B$13+ROW()-2)/MAX(INDEX(Prices!D$2:D$247,Inputs!$B$13):INDEX(Prices!D$2:D$247,Inputs!$B$13+ROW()-2))-1 -> -0.0020660676 | E3: =INDEX(Prices!E$2:E$247,Inputs!$B$13+ROW()-2)/MAX(INDEX(Prices!E$2:E$247,Inputs!$B$13):INDEX(Prices!E$2:E$247,Inputs!$B$13+ROW()-2))-1 -> 0 | F3: =INDEX(Prices!F$2:F$247,Inputs!$B$13+ROW()-2)/MAX(INDEX(Prices!F$2:F$247,Inputs!$B$13):INDEX(Prices!F$2:F$247,Inputs!$B$13+ROW()-2))-1 -> 0 | G3: =INDEX(Prices!G$2:G$247,Inputs!$B$13+ROW()-2)/MAX(INDEX(Prices!G$2:G$247,Inputs!$B$13):INDEX(Prices!G$2:G$247,Inputs!$B$13+ROW()-2))-1 -> 0 | H3: =INDEX(Prices!H$2:H$247,Inputs!$B$13+ROW()-2)/MAX(INDEX(Prices!H$2:H$247,Inputs!$B$13):INDEX(Prices!H$2:H$247,Inputs!$B$13+ROW()-2))-1 -> 0
A4: =INDEX(Prices!$A$2:$A$247,Inputs!$B$13+ROW()-2) -> 46223 | B4: =INDEX(Prices!B$2:B$247,Inputs!$B$13+ROW()-2)/MAX(INDEX(Prices!B$2:B$247,Inputs!$B$13):INDEX(Prices!B$2:B$247,Inputs!$B$13+ROW()-2))-1 -> -0.0039368299 | C4: =INDEX(Prices!C$2:C$247,Inputs!$B$13+ROW()-2)/MAX(INDEX(Prices!C$2:C$247,Inputs!$B$13):INDEX(Prices!C$2:C$247,Inputs!$B$13+ROW()-2))-1 -> 0 | D4: =INDEX(Prices!D$2:D$247,Inputs!$B$13+ROW()-2)/MAX(INDEX(Prices!D$2:D$247,Inputs!$B$13):INDEX(Prices!D$2:D$247,Inputs!$B$13+ROW()-2))-1 -> -0.00050682009 | E4: =INDEX(Prices!E$2:E$247,Inputs!$B$13+ROW()-2)/MAX(INDEX(Prices!E$2:E$247,Inputs!$B$13):INDEX(Prices!E$2:E$247,Inputs!$B$13+ROW()-2))-1 -> -0.0098493884 | F4: =INDEX(Prices!F$2:F$247,Inputs!$B$13+ROW()-2)/MAX(INDEX(Prices!F$2:F$247,Inputs!$B$13):INDEX(Prices!F$2:F$247,Inputs!$B$13+ROW()-2))-1 -> -0.0022154476 | G4: =INDEX(Prices!G$2:G$247,Inputs!$B$13+ROW()-2)/MAX(INDEX(Prices!G$2:G$247,Inputs!$B$13):INDEX(Prices!G$2:G$247,Inputs!$B$13+ROW()-2))-1 -> 0 | H4: =INDEX(Prices!H$2:H$247,Inputs!$B$13+ROW()-2)/MAX(INDEX(Prices!H$2:H$247,Inputs!$B$13):INDEX(Prices!H$2:H$247,Inputs!$B$13+ROW()-2))-1 -> -0.0026347107
A5: =INDEX(Prices!$A$2:$A$247,Inputs!$B$13+ROW()-2) -> 46224 | B5: =INDEX(Prices!B$2:B$247,Inputs!$B$13+ROW()-2)/MAX(INDEX(Prices!B$2:B$247,Inputs!$B$13):INDEX(Prices!B$2:B$247,Inputs!$B$13+ROW()-2))-1 -> -0.0060244182 | C5: =INDEX(Prices!C$2:C$247,Inputs!$B$13+ROW()-2)/MAX(INDEX(Prices!C$2:C$247,Inputs!$B$13):INDEX(Prices!C$2:C$247,Inputs!$B$13+ROW()-2))-1 -> 0 | D5: =INDEX(Prices!D$2:D$247,Inputs!$B$13+ROW()-2)/MAX(INDEX(Prices!D$2:D$247,Inputs!$B$13):INDEX(Prices!D$2:D$247,Inputs!$B$13+ROW()-2))-1 -> 0 | E5: =INDEX(Prices!E$2:E$247,Inputs!$B$13+ROW()-2)/MAX(INDEX(Prices!E$2:E$247,Inputs!$B$13):INDEX(Prices!E$2:E$247,Inputs!$B$13+ROW()-2))-1 -> -0.011723062 | F5: =INDEX(Prices!F$2:F$247,Inputs!$B$13+ROW()-2)/MAX(INDEX(Prices!F$2:F$247,Inputs!$B$13):INDEX(Prices!F$2:F$247,Inputs!$B$13+ROW()-2))-1 -> -0.0082869715 | G5: =INDEX(Prices!G$2:G$247,Inputs!$B$13+ROW()-2)/MAX(INDEX(Prices!G$2:G$247,Inputs!$B$13):INDEX(Prices!G$2:G$247,Inputs!$B$13+ROW()-2))-1 -> -0.0030621114 | H5: =INDEX(Prices!H$2:H$247,Inputs!$B$13+ROW()-2)/MAX(INDEX(Prices!H$2:H$247,Inputs!$B$13):INDEX(Prices!H$2:H$247,Inputs!$B$13+ROW()-2))-1 -> 0
A6: =INDEX(Prices!$A$2:$A$247,Inputs!$B$13+ROW()-2) -> 46225 | B6: =INDEX(Prices!B$2:B$247,Inputs!$B$13+ROW()-2)/MAX(INDEX(Prices!B$2:B$247,Inputs!$B$13):INDEX(Prices!B$2:B$247,Inputs!$B$13+ROW()-2))-1 -> -0.013891914 | C6: =INDEX(Prices!C$2:C$247,Inputs!$B$13+ROW()-2)/MAX(INDEX(Prices!C$2:C$247,Inputs!$B$13):INDEX(Prices!C$2:C$247,Inputs!$B$13+ROW()-2))-1 -> -0.010906909 | D6: =INDEX(Prices!D$2:D$247,Inputs!$B$13+ROW()-2)/MAX(INDEX(Prices!D$2:D$247,Inputs!$B$13):INDEX(Prices!D$2:D$247,Inputs!$B$13+ROW()-2))-1 -> -0.015379825 | E6: =INDEX(Prices!E$2:E$247,Inputs!$B$13+ROW()-2)/MAX(INDEX(Prices!E$2:E$247,Inputs!$B$13):INDEX(Prices!E$2:E$247,Inputs!$B$13+ROW()-2))-1 -> -0.023830599 | F6: =INDEX(Prices!F$2:F$247,Inputs!$B$13+ROW()-2)/MAX(INDEX(Prices!F$2:F$247,Inputs!$B$13):INDEX(Prices!F$2:F$247,Inputs!$B$13+ROW()-2))-1 -> -0.023155276 | G6: =INDEX(Prices!G$2:G$247,Inputs!$B$13+ROW()-2)/MAX(INDEX(Prices!G$2:G$247,Inputs!$B$13):INDEX(Prices!G$2:G$247,Inputs!$B$13+ROW()-2))-1 -> 0 | H6: =INDEX(Prices!H$2:H$247,Inputs!$B$13+ROW()-2)/MAX(INDEX(Prices!H$2:H$247,Inputs!$B$13):INDEX(Prices!H$2:H$247,Inputs!$B$13+ROW()-2))-1 -> 0
A7: =INDEX(Prices!$A$2:$A$247,Inputs!$B$13+ROW()-2) -> 46226 | B7: =INDEX(Prices!B$2:B$247,Inputs!$B$13+ROW()-2)/MAX(INDEX(Prices!B$2:B$247,Inputs!$B$13):INDEX(Prices!B$2:B$247,Inputs!$B$13+ROW()-2))-1 -> -0.019096502 | C7: =INDEX(Prices!C$2:C$247,Inputs!$B$13+ROW()-2)/MAX(INDEX(Prices!C$2:C$247,Inputs!$B$13):INDEX(Prices!C$2:C$247,Inputs!$B$13+ROW()-2))-1 -> -0.020680261 | D7: =INDEX(Prices!D$2:D$247,Inputs!$B$13+ROW()-2)/MAX(INDEX(Prices!D$2:D$247,Inputs!$B$13):INDEX(Prices!D$2:D$247,Inputs!$B$13+ROW()-2))-1 -> -0.025308767 | E7: =INDEX(Prices!E$2:E$247,Inputs!$B$13+ROW()-2)/MAX(INDEX(Prices!E$2:E$247,Inputs!$B$13):INDEX(Prices!E$2:E$247,Inputs!$B$13+ROW()-2))-1 -> -0.032969136 | F7: =INDEX(Prices!F$2:F$247,Inputs!$B$13+ROW()-2)/MAX(INDEX(Prices!F$2:F$247,Inputs!$B$13):INDEX(Prices!F$2:F$247,Inputs!$B$13+ROW()-2))-1 -> -0.023712987 | G7: =INDEX(Prices!G$2:G$247,Inputs!$B$13+ROW()-2)/MAX(INDEX(Prices!G$2:G$247,Inputs!$B$13):INDEX(Prices!G$2:G$247,Inputs!$B$13+ROW()-2))-1 -> -0.0040744367 | H7: =INDEX(Prices!H$2:H$247,Inputs!$B$13+ROW()-2)/MAX(INDEX(Prices!H$2:H$247,Inputs!$B$13):INDEX(Prices!H$2:H$247,Inputs!$B$13+ROW()-2))-1 -> 0
A8: =INDEX(Prices!$A$2:$A$247,Inputs!$B$13+ROW()-2) -> 46227 | B8: =INDEX(Prices!B$2:B$247,Inputs!$B$13+ROW()-2)/MAX(INDEX(Prices!B$2:B$247,Inputs!$B$13):INDEX(Prices!B$2:B$247,Inputs!$B$13+ROW()-2))-1 -> -0.02329428 | C8: =INDEX(Prices!C$2:C$247,Inputs!$B$13+ROW()-2)/MAX(INDEX(Prices!C$2:C$247,Inputs!$B$13):INDEX(Prices!C$2:C$247,Inputs!$B$13+ROW()-2))-1 -> -0.021674901 | D8: =INDEX(Prices!D$2:D$247,Inputs!$B$13+ROW()-2)/MAX(INDEX(Prices!D$2:D$247,Inputs!$B$13):INDEX(Prices!D$2:D$247,Inputs!$B$13+ROW()-2))-1 -> -0.028469146 | E8: =INDEX(Prices!E$2:E$247,Inputs!$B$13+ROW()-2)/MAX(INDEX(Prices!E$2:E$247,Inputs!$B$13):INDEX(Prices!E$2:E$247,Inputs!$B$13+ROW()-2))-1 -> -0.031234728 | F8: =INDEX(Prices!F$2:F$247,Inputs!$B$13+ROW()-2)/MAX(INDEX(Prices!F$2:F$247,Inputs!$B$13):INDEX(Prices!F$2:F$247,Inputs!$B$13+ROW()-2))-1 -> -0.015692896 | G8: =INDEX(Prices!G$2:G$247,Inputs!$B$13+ROW()-2)/MAX(INDEX(Prices!G$2:G$247,Inputs!$B$13):INDEX(Prices!G$2:G$247,Inputs!$B$13+ROW()-2))-1 -> -0.0036661806 | H8: =INDEX(Prices!H$2:H$247,Inputs!$B$13+ROW()-2)/MAX(INDEX(Prices!H$2:H$247,Inputs!$B$13):INDEX(Prices!H$2:H$247,Inputs!$B$13+ROW()-2))-1 -> -0.011004404
A9: =INDEX(Prices!$A$2:$A$247,Inputs!$B$13+ROW()-2) -> 46230 | B9: =INDEX(Prices!B$2:B$247,Inputs!$B$13+ROW()-2)/MAX(INDEX(Prices!B$2:B$247,Inputs!$B$13):INDEX(Prices!B$2:B$247,Inputs!$B$13+ROW()-2))-1 -> -0.013904242 | C9: =INDEX(Prices!C$2:C$247,Inputs!$B$13+ROW()-2)/MAX(INDEX(Prices!C$2:C$247,Inputs!$B$13):INDEX(Prices!C$2:C$247,Inputs!$B$13+ROW()-2))-1 -> -0.010858486 | D9: =INDEX(Prices!D$2:D$247,Inputs!$B$13+ROW()-2)/MAX(INDEX(Prices!D$2:D$247,Inputs!$B$13):INDEX(Prices!D$2:D$247,Inputs!$B$13+ROW()-2))-1 -> -0.015722113 | E9: =INDEX(Prices!E$2:E$247,Inputs!$B$13+ROW()-2)/MAX(INDEX(Prices!E$2:E$247,Inputs!$B$13):INDEX(Prices!E$2:E$247,Inputs!$B$13+ROW()-2))-1 -> -0.024507274 | F9: =INDEX(Prices!F$2:F$247,Inputs!$B$13+ROW()-2)/MAX(INDEX(Prices!F$2:F$247,Inputs!$B$13):INDEX(Prices!F$2:F$247,Inputs!$B$13+ROW()-2))-1 -> 0 | G9: =INDEX(Prices!G$2:G$247,Inputs!$B$13+ROW()-2)/MAX(INDEX(Prices!G$2:G$247,Inputs!$B$13):INDEX(Prices!G$2:G$247,Inputs!$B$13+ROW()-2))-1 -> 0 | H9: =INDEX(Prices!H$2:H$247,Inputs!$B$13+ROW()-2)/MAX(INDEX(Prices!H$2:H$247,Inputs!$B$13):INDEX(Prices!H$2:H$247,Inputs!$B$13+ROW()-2))-1 -> 0
A10: =INDEX(Prices!$A$2:$A$247,Inputs!$B$13+ROW()-2) -> 46231 | B10: =INDEX(Prices!B$2:B$247,Inputs!$B$13+ROW()-2)/MAX(INDEX(Prices!B$2:B$247,Inputs!$B$13):INDEX(Prices!B$2:B$247,Inputs!$B$13+ROW()-2))-1 -> -0.014339841 | C10: =INDEX(Prices!C$2:C$247,Inputs!$B$13+ROW()-2)/MAX(INDEX(Prices!C$2:C$247,Inputs!$B$13):INDEX(Prices!C$2:C$247,Inputs!$B$13+ROW()-2))-1 -> -0.010098813 | D10: =INDEX(Prices!D$2:D$247,Inputs!$B$13+ROW()-2)/MAX(INDEX(Prices!D$2:D$247,Inputs!$B$13):INDEX(Prices!D$2:D$247,Inputs!$B$13+ROW()-2))-1 -> -0.017878789 | E10: =INDEX(Prices!E$2:E$247,Inputs!$B$13+ROW()-2)/MAX(INDEX(Prices!E$2:E$247,Inputs!$B$13):INDEX(Prices!E$2:E$247,Inputs!$B$13+ROW()-2))-1 -> -0.030173578 | F10: =INDEX(Prices!F$2:F$247,Inputs!$B$13+ROW()-2)/MAX(INDEX(Prices!F$2:F$247,Inputs!$B$13):INDEX(Prices!F$2:F$247,Inputs!$B$13+ROW()-2))-1 -> 0 | G10: =INDEX(Prices!G$2:G$247,Inputs!$B$13+ROW()-2)/MAX(INDEX(Prices!G$2:G$247,Inputs!$B$13):INDEX(Prices!G$2:G$247,Inputs!$B$13+ROW()-2))-1 -> -0.013792046 | H10: =INDEX(Prices!H$2:H$247,Inputs!$B$13+ROW()-2)/MAX(INDEX(Prices!H$2:H$247,Inputs!$B$13):INDEX(Prices!H$2:H$247,Inputs!$B$13+ROW()-2))-1 -> 0
A11: =INDEX(Prices!$A$2:$A$247,Inputs!$B$13+ROW()-2) -> 46232 | B11: =INDEX(Prices!B$2:B$247,Inputs!$B$13+ROW()-2)/MAX(INDEX(Prices!B$2:B$247,Inputs!$B$13):INDEX(Prices!B$2:B$247,Inputs!$B$13+ROW()-2))-1 -> -0.0034560271 | C11: =INDEX(Prices!C$2:C$247,Inputs!$B$13+ROW()-2)/MAX(INDEX(Prices!C$2:C$247,Inputs!$B$13):INDEX(Prices!C$2:C$247,Inputs!$B$13+ROW()-2))-1 -> -0.0019900742 | D11: =INDEX(Prices!D$2:D$247,Inputs!$B$13+ROW()-2)/MAX(INDEX(Prices!D$2:D$247,Inputs!$B$13):INDEX(Prices!D$2:D$247,Inputs!$B$13+ROW()-2))-1 -> -0.0033817084 | E11: =INDEX(Prices!E$2:E$247,Inputs!$B$13+ROW()-2)/MAX(INDEX(Prices!E$2:E$247,Inputs!$B$13):INDEX(Prices!E$2:E$247,Inputs!$B$13+ROW()-2))-1 -> -0.022478956 | F11: =INDEX(Prices!F$2:F$247,Inputs!$B$13+ROW()-2)/MAX(INDEX(Prices!F$2:F$247,Inputs!$B$13):INDEX(Prices!F$2:F$247,Inputs!$B$13+ROW()-2))-1 -> 0 | G11: =INDEX(Prices!G$2:G$247,Inputs!$B$13+ROW()-2)/MAX(INDEX(Prices!G$2:G$247,Inputs!$B$13):INDEX(Prices!G$2:G$247,Inputs!$B$13+ROW()-2))-1 -> 0 | H11: =INDEX(Prices!H$2:H$247,Inputs!$B$13+ROW()-2)/MAX(INDEX(Prices!H$2:H$247,Inputs!$B$13):INDEX(Prices!H$2:H$247,Inputs!$B$13+ROW()-2))-1 -> -0.00064466544
A12: =INDEX(Prices!$A$2:$A$247,Inputs!$B$13+ROW()-2) -> 46233 | B12: =INDEX(Prices!B$2:B$247,Inputs!$B$13+ROW()-2)/MAX(INDEX(Prices!B$2:B$247,Inputs!$B$13):INDEX(Prices!B$2:B$247,Inputs!$B$13+ROW()-2))-1 -> -0.00070476652 | C12: =INDEX(Prices!C$2:C$247,Inputs!$B$13+ROW()-2)/MAX(INDEX(Prices!C$2:C$247,Inputs!$B$13):INDEX(Prices!C$2:C$247,Inputs!$B$13+ROW()-2))-1 -> -0.0054907633 | D12: =INDEX(Prices!D$2:D$247,Inputs!$B$13+ROW()-2)/MAX(INDEX(Prices!D$2:D$247,Inputs!$B$13):INDEX(Prices!D$2:D$247,Inputs!$B$13+ROW()-2))-1 -> -0.0089355339 | E12: =INDEX(Prices!E$2:E$247,Inputs!$B$13+ROW()-2)/MAX(INDEX(Prices!E$2:E$247,Inputs!$B$13):INDEX(Prices!E$2:E$247,Inputs!$B$13+ROW()-2))-1 -> -0.023476882 | F12: =INDEX(Prices!F$2:F$247,Inputs!$B$13+ROW()-2)/MAX(INDEX(Prices!F$2:F$247,Inputs!$B$13):INDEX(Prices!F$2:F$247,Inputs!$B$13+ROW()-2))-1 -> 0 | G12: =INDEX(Prices!G$2:G$247,Inputs!$B$13+ROW()-2)/MAX(INDEX(Prices!G$2:G$247,Inputs!$B$13):INDEX(Prices!G$2:G$247,Inputs!$B$13+ROW()-2))-1 -> -0.0009780512 | H12: =INDEX(Prices!H$2:H$247,Inputs!$B$13+ROW()-2)/MAX(INDEX(Prices!H$2:H$247,Inputs!$B$13):INDEX(Prices!H$2:H$247,Inputs!$B$13+ROW()-2))-1 -> 0
A13: =INDEX(Prices!$A$2:$A$247,Inputs!$B$13+ROW()-2) -> 46234 | B13: =INDEX(Prices!B$2:B$247,Inputs!$B$13+ROW()-2)/MAX(INDEX(Prices!B$2:B$247,Inputs!$B$13):INDEX(Prices!B$2:B$247,Inputs!$B$13+ROW()-2))-1 -> 0 | C13: =INDEX(Prices!C$2:C$247,Inputs!$B$13+ROW()-2)/MAX(INDEX(Prices!C$2:C$247,Inputs!$B$13):INDEX(Prices!C$2:C$247,Inputs!$B$13+ROW()-2))-1 -> -0.001147845 | D13: =INDEX(Prices!D$2:D$247,Inputs!$B$13+ROW()-2)/MAX(INDEX(Prices!D$2:D$247,Inputs!$B$13):INDEX(Prices!D$2:D$247,Inputs!$B$13+ROW()-2))-1 -> -0.0045501221 | E13: =INDEX(Prices!E$2:E$247,Inputs!$B$13+ROW()-2)/MAX(INDEX(Prices!E$2:E$247,Inputs!$B$13):INDEX(Prices!E$2:E$247,Inputs!$B$13+ROW()-2))-1 -> -0.021471633 | F13: =INDEX(Prices!F$2:F$247,Inputs!$B$13+ROW()-2)/MAX(INDEX(Prices!F$2:F$247,Inputs!$B$13):INDEX(Prices!F$2:F$247,Inputs!$B$13+ROW()-2))-1 -> -0.015568425 | G13: =INDEX(Prices!G$2:G$247,Inputs!$B$13+ROW()-2)/MAX(INDEX(Prices!G$2:G$247,Inputs!$B$13):INDEX(Prices!G$2:G$247,Inputs!$B$13+ROW()-2))-1 -> -0.011459902 | H13: =INDEX(Prices!H$2:H$247,Inputs!$B$13+ROW()-2)/MAX(INDEX(Prices!H$2:H$247,Inputs!$B$13):INDEX(Prices!H$2:H$247,Inputs!$B$13+ROW()-2))-1 -> 0
... A66: =INDEX(Prices!$A$2:$A$247,Inputs!$B$13+ROW()-2) -> 46311 | B66: =INDEX(Prices!B$2:B$247,Inputs!$B$13+ROW()-2)/MAX(INDEX(Prices!B$2:B$247,Inputs!$B$13):INDEX(Prices!B$2:B$247,Inputs!$B$13+ROW()-2))-1 -> -0.065719314 | C66: =INDEX(Prices!C$2:C$247,Inputs!$B$13+ROW()-2)/MAX(INDEX(Prices!C$2:C$247,Inputs!$B$13):INDEX(Prices!C$2:C$247,Inputs!$B$13+ROW()-2))-1 -> -0.079330788 | D66: =INDEX(Prices!D$2:D$247,Inputs!$B$13+ROW()-2)/MAX(INDEX(Prices!D$2:D$247,Inputs!$B$13):INDEX(Prices!D$2:D$247,Inputs!$B$13+ROW()-2))-1 -> -0.049864034 | E66: =INDEX(Prices!E$2:E$247,Inputs!$B$13+ROW()-2)/MAX(INDEX(Prices!E$2:E$247,Inputs!$B$13):INDEX(Prices!E$2:E$247,Inputs!$B$13+ROW()-2))-1 -> -0.045750785 | F66: =INDEX(Prices!F$2:F$247,Inputs!$B$13+ROW()-2)/MAX(INDEX(Prices!F$2:F$247,Inputs!$B$13):INDEX(Prices!F$2:F$247,Inputs!$B$13+ROW()-2))-1 -> 0 | G66: =INDEX(Prices!G$2:G$247,Inputs!$B$13+ROW()-2)/MAX(INDEX(Prices!G$2:G$247,Inputs!$B$13):INDEX(Prices!G$2:G$247,Inputs!$B$13+ROW()-2))-1 -> -0.10706266 | H66: =INDEX(Prices!H$2:H$247,Inputs!$B$13+ROW()-2)/MAX(INDEX(Prices!H$2:H$247,Inputs!$B$13):INDEX(Prices!H$2:H$247,Inputs!$B$13+ROW()-2))-1 -> -0.13084907
A68: Max drawdown | B68: =MIN(B2:B66) -> -0.10262651 | C68: =MIN(C2:C66) -> -0.098750871 | D68: =MIN(D2:D66) -> -0.053822562 | E68: =MIN(E2:E66) -> -0.072818661 | F68: =MIN(F2:F66) -> -0.13050719 | G68: =MIN(G2:G66) -> -0.12360004 | H68: =MIN(H2:H66) -> -0.1732062

Sheet Daily
A1: Date | B1: NIFTY 50 | C1: NIFTY MIDCAP 100 | D1: NIFTY SMALLCAP 100 | E1: NIFTY BANK | F1: NIFTY IT | G1: NIFTY FMCG | H1: NIFTY AUTO
A2: =Prices!A2 -> 45950
A3: =Prices!A3 -> 45951 | B3: =Prices!B3/Prices!B2-1 -> 0.00098478707 | C3: =Prices!C3/Prices!C2-1 -> 0.001096142 | D3: =Prices!D3/Prices!D2-1 -> 0.0051905537 | E3: =Prices!E3/Prices!E2-1 -> -0.00044801941 | F3: =Prices!F3/Prices!F2-1 -> 0.00020259204 | G3: =Prices!G3/Prices!G2-1 -> 0.00021202481 | H3: =Prices!H3/Prices!H2-1 -> 0.0016332266
A4: =Prices!A4 -> 45953 | B4: =Prices!B4/Prices!B3-1 -> 0.00088137742 | C4: =Prices!C4/Prices!C3-1 -> -0.0006446775 | D4: =Prices!D4/Prices!D3-1 -> -0.00050271438 | E4: =Prices!E4/Prices!E3-1 -> 0.0012214001 | F4: =Prices!F4/Prices!F3-1 -> 0.022065312 | G4: =Prices!G4/Prices!G3-1 -> 0.0028846927 | H4: =Prices!H4/Prices!H3-1 -> -0.00040764088
A5: =Prices!A5 -> 45954 | B5: =Prices!B5/Prices!B4-1 -> -0.0037174506 | C5: =Prices!C5/Prices!C4-1 -> -0.0023588858 | D5: =Prices!D5/Prices!D4-1 -> -0.0020829404 | E5: =Prices!E5/Prices!E4-1 -> -0.0065162312 | F5: =Prices!F5/Prices!F4-1 -> -0.0025582997 | G5: =Prices!G5/Prices!G4-1 -> -0.0074745761 | H5: =Prices!H5/Prices!H4-1 -> -0.0040431688
A6: =Prices!A6 -> 45957 | B6: =Prices!B6/Prices!B5-1 -> 0.0066252765 | C6: =Prices!C6/Prices!C5-1 -> 0.0092679196 | D6: =Prices!D6/Prices!D5-1 -> 0.0082012343 | E6: =Prices!E6/Prices!E5-1 -> 0.0071863583 | F6: =Prices!F6/Prices!F5-1 -> 0.0039667818 | G6: =Prices!G6/Prices!G5-1 -> 0.001434831 | H6: =Prices!H6/Prices!H5-1 -> 0.0057158772
A7: =Prices!A7 -> 45958 | B7: =Prices!B7/Prices!B6-1 -> -0.001149578 | C7: =Prices!C7/Prices!C6-1 -> -0.00024757382 | D7: =Prices!D7/Prices!D6-1 -> 0.00024724163 | E7: =Prices!E7/Prices!E6-1 -> 0.0017181672 | F7: =Prices!F7/Prices!F6-1 -> -0.0074372182 | G7: =Prices!G7/Prices!G6-1 -> -0.0056513545 | H7: =Prices!H7/Prices!H6-1 -> -0.0042290742
A8: =Prices!A8 -> 45959 | B8: =Prices!B8/Prices!B7-1 -> 0.0045380588 | C8: =Prices!C8/Prices!C7-1 -> 0.006420108 | D8: =Prices!D8/Prices!D7-1 -> 0.0043433147 | E8: =Prices!E8/Prices!E7-1 -> 0.0029400094 | F8: =Prices!F8/Prices!F7-1 -> 0.0064053943 | G8: =Prices!G8/Prices!G7-1 -> 0.0090055168 | H8: =Prices!H8/Prices!H7-1 -> -0.0073466712
A9: =Prices!A9 -> 45960 | B9: =Prices!B9/Prices!B8-1 -> -0.0067571458 | C9: =Prices!C9/Prices!C8-1 -> -0.00087781935 | D9: =Prices!D9/Prices!D8-1 -> -0.00096551463 | E9: =Prices!E9/Prices!E8-1 -> -0.0060657443 | F9: =Prices!F9/Prices!F8-1 -> -0.0050900385 | G9: =Prices!G9/Prices!G8-1 -> -0.0048017013 | H9: =Prices!H9/Prices!H8-1 -> -0.0044287522
A10: =Prices!A10 -> 45961 | B10: =Prices!B10/Prices!B9-1 -> -0.0060186607 | C10: =Prices!C10/Prices!C9-1 -> -0.0044986168 | D10: =Prices!D10/Prices!D9-1 -> -0.0048132888 | E10: =Prices!E10/Prices!E9-1 -> -0.0043898875 | F10: =Prices!F10/Prices!F9-1 -> -0.005404329 | G10: =Prices!G10/Prices!G9-1 -> -0.0023960173 | H10: =Prices!H10/Prices!H9-1 -> -0.00073426502
A11: =Prices!A11 -> 45964 | B11: =Prices!B11/Prices!B10-1 -> 0.0016036793 | C11: =Prices!C11/Prices!C10-1 -> 0.0077140503 | D11: =Prices!D11/Prices!D10-1 -> 0.0072140494 | E11: =Prices!E11/Prices!E10-1 -> 0.0056268698 | F11: =Prices!F11/Prices!F10-1 -> -0.00166049 | G11: =Prices!G11/Prices!G10-1 -> -0.00097494151 | H11: =Prices!H11/Prices!H10-1 -> 0.0011917262
A12: =Prices!A12 -> 45965 | B12: =Prices!B12/Prices!B11-1 -> -0.006431617 | C12: =Prices!C12/Prices!C11-1 -> -0.0041501209 | D12: =Prices!D12/Prices!D11-1 -> -0.0082372768 | E12: =Prices!E12/Prices!E11-1 -> -0.0047227737 | F12: =Prices!F12/Prices!F11-1 -> -0.010616203 | G12: =Prices!G12/Prices!G11-1 -> -0.0060209746 | H12: =Prices!H12/Prices!H11-1 -> -0.0086339217
A13: =Prices!A13 -> 45967 | B13: =Prices!B13/Prices!B12-1 -> -0.0034358623 | C13: =Prices!C13/Prices!C12-1 -> -0.0094707948 | D13: =Prices!D13/Prices!D12-1 -> -0.013937225 | E13: =Prices!E13/Prices!E12-1 -> -0.0047175154 | F13: =Prices!F13/Prices!F12-1 -> 0.0017874076 | G13: =Prices!G13/Prices!G12-1 -> -0.0018605909 | H13: =Prices!H13/Prices!H12-1 -> 0.00061818749
A14: =Prices!A14 -> 45968 | B14: =Prices!B14/Prices!B13-1 -> -0.00068209348 | C14: =Prices!C14/Prices!C13-1 -> 0.0062982818 | D14: =Prices!D14/Prices!D13-1 -> -0.0016045291 | E14: =Prices!E14/Prices!E13-1 -> 0.0056042777 | F14: =Prices!F14/Prices!F13-1 -> -0.0062256633 | G14: =Prices!G14/Prices!G13-1 -> -0.0049280448 | H14: =Prices!H14/Prices!H13-1 -> 0.005748033
... A247: =Prices!A247 -> 46311 | B247: =Prices!B247/Prices!B246-1 -> 0.0064703107 | C247: =Prices!C247/Prices!C246-1 -> -0.0011402557 | D247: =Prices!D247/Prices!D246-1 -> -9.9311614e-05 | E247: =Prices!E247/Prices!E246-1 -> 0.00060024547 | F247: =Prices!F247/Prices!F246-1 -> 0.039202729 | G247: =Prices!G247/Prices!G246-1 -> -0.003918141 | H247: =Prices!H247/Prices!H246-1 -> 0.0075108303

Sheet Volatility
A1: Date | B1: NIFTY 50 | C1: NIFTY MIDCAP 100 | D1: NIFTY SMALLCAP 100 | E1: NIFTY BANK | F1: NIFTY IT | G1: NIFTY FMCG | H1: NIFTY AUTO | J1: 20-day rolling volatility, annualised. First value appears after 20 daily returns.
A2: =Prices!A2 -> 45950
A3: =Prices!A3 -> 45951
A4: =Prices!A4 -> 45953
A5: =Prices!A5 -> 45954
A6: =Prices!A6 -> 45957
A7: =Prices!A7 -> 45958
A8: =Prices!A8 -> 45959
A9: =Prices!A9 -> 45960
A10: =Prices!A10 -> 45961
A11: =Prices!A11 -> 45964
A12: =Prices!A12 -> 45965
A13: =Prices!A13 -> 45967
... A21: =Prices!A21 -> 45979
A22: =Prices!A22 -> 45980 | B22: =STDEV(Daily!B3:B22)*SQRT(Inputs!$B$16) -> 0.069257844 | C22: =STDEV(Daily!C3:C22)*SQRT(Inputs!$B$16) -> 0.084503546 | D22: =STDEV(Daily!D3:D22)*SQRT(Inputs!$B$16) -> 0.098021819 | E22: =STDEV(Daily!E3:E22)*SQRT(Inputs!$B$16) -> 0.069642706 | F22: =STDEV(Daily!F3:F22)*SQRT(Inputs!$B$16) -> 0.187768 | G22: =STDEV(Daily!G3:G22)*SQRT(Inputs!$B$16) -> 0.069161641 | H22: =STDEV(Daily!H3:H22)*SQRT(Inputs!$B$16) -> 0.093672039
A23: =Prices!A23 -> 45981 | B23: =STDEV(Daily!B4:B23)*SQRT(Inputs!$B$16) -> 0.071439077 | C23: =STDEV(Daily!C4:C23)*SQRT(Inputs!$B$16) -> 0.084592378 | D23: =STDEV(Daily!D4:D23)*SQRT(Inputs!$B$16) -> 0.095819785 | E23: =STDEV(Daily!E4:E23)*SQRT(Inputs!$B$16) -> 0.069542057 | F23: =STDEV(Daily!F4:F23)*SQRT(Inputs!$B$16) -> 0.18780855 | G23: =STDEV(Daily!G4:G23)*SQRT(Inputs!$B$16) -> 0.069348471 | H23: =STDEV(Daily!H4:H23)*SQRT(Inputs!$B$16) -> 0.094614272
A24: =Prices!A24 -> 45982 | B24: =STDEV(Daily!B5:B24)*SQRT(Inputs!$B$16) -> 0.0739164 | C24: =STDEV(Daily!C5:C24)*SQRT(Inputs!$B$16) -> 0.095545807 | D24: =STDEV(Daily!D5:D24)*SQRT(Inputs!$B$16) -> 0.10419663 | E24: =STDEV(Daily!E5:E24)*SQRT(Inputs!$B$16) -> 0.076882646 | F24: =STDEV(Daily!F5:F24)*SQRT(Inputs!$B$16) -> 0.17414811 | G24: =STDEV(Daily!G5:G24)*SQRT(Inputs!$B$16) -> 0.06843006 | H24: =STDEV(Daily!H5:H24)*SQRT(Inputs!$B$16) -> 0.094641818
A25: =Prices!A25 -> 45985 | B25: =STDEV(Daily!B6:B25)*SQRT(Inputs!$B$16) -> 0.074261704 | C25: =STDEV(Daily!C6:C25)*SQRT(Inputs!$B$16) -> 0.095973786 | D25: =STDEV(Daily!D6:D25)*SQRT(Inputs!$B$16) -> 0.10731998 | E25: =STDEV(Daily!E6:E25)*SQRT(Inputs!$B$16) -> 0.072246061 | F25: =STDEV(Daily!F6:F25)*SQRT(Inputs!$B$16) -> 0.17387209 | G25: =STDEV(Daily!G6:G25)*SQRT(Inputs!$B$16) -> 0.067420031 | H25: =STDEV(Daily!H6:H25)*SQRT(Inputs!$B$16) -> 0.094292053
